{"asctime": "2025-05-23 05:53:04,903", "levelname": "DEBUG", "name": "django.template", "module": "base", "funcName": "_resolve_lookup", "lineno": 933, "message": "Exception while resolving variable 'error' in template 'trading/orden_resultado.html'.", "exc_info": "Traceback (most recent call last):\n  File \"C:\\Users\\Eliana Galban\\AppData\\Local\\Programs\\Python\\Python312\\Lib\\site-packages\\django\\template\\base.py\", line 883, in _resolve_lookup\n    current = current[bit]\n              ~~~~~~~^^^^^\nKeyError: 'error'\n\nDuring handling of the above exception, another exception occurred:\n\nTraceback (most recent call last):\n  File \"C:\\Users\\Eliana Galban\\AppData\\Local\\Programs\\Python\\Python312\\Lib\\site-packages\\django\\template\\base.py\", line 893, in _resolve_lookup\n    current = getattr(current, bit)\n              ^^^^^^^^^^^^^^^^^^^^^\nAttributeError: 'dict' object has no attribute 'error'\n\nDuring handling of the above exception, another exception occurred:\n\nTraceback (most recent call last):\n  File \"C:\\Users\\Eliana Galban\\AppData\\Local\\Programs\\Python\\Python312\\Lib\\site-packages\\django\\template\\base.py\", line 899, in _resolve_lookup\n    current = current[int(bit)]\n                      ^^^^^^^^\nValueError: invalid literal for int() with base 10: 'error'\n\nDuring handling of the above exception, another exception occurred:\n\nTraceback (most recent call last):\n  File \"C:\\Users\\Eliana Galban\\AppData\\Local\\Programs\\Python\\Python312\\Lib\\site-packages\\django\\template\\base.py\", line 906, in _resolve_lookup\n    raise VariableDoesNotExist(\ndjango.template.base.VariableDoesNotExist: Failed lookup for key [error] in {'data': {'id': '6304a063-3f5b-48c2-a0f1-94b03fca150a', 'client_order_id': '12980e33-18c1-45b7-ac97-d86d7ded3661', 'created_at': '2025-05-23T10:53:05.017835192Z', 'updated_at': '2025-05-23T10:53:05.019181042Z', 'submitted_at': '2025-05-23T10:53:05.017835192Z', 'filled_at': None, 'expired_at': None, 'canceled_at': None, 'failed_at': None, 'replaced_at': None, 'replaced_by': None, 'replaces': None, 'asset_id': '0e967a96-2a81-4eaf-91cc-83d5cce69717', 'symbol': 'MRVI', 'asset_class': 'us_equity', 'notional': None, 'qty': '1', 'filled_qty': '0', 'filled_avg_price': None, 'order_class': '', 'order_type': 'market', 'type': 'market', 'side': 'buy', 'position_intent': 'buy_to_open', 'time_in_force': 'gtc', 'limit_price': None, 'stop_price': None, 'status': 'accepted', 'extended_hours': False, 'legs': None, 'trail_percent': None, 'trail_price': None, 'hwm': None, 'commission': '0', 'subtag': None, 'source': None, 'expires_at': '2025-08-21T20:00:00Z'}, 'order_id': '6304a063-3f5b-48c2-a0f1-94b03fca150a', 'status': 'accepted'}"}
{"asctime": "2025-05-23 05:53:05,011", "levelname": "DEBUG", "name": "django.template", "module": "base", "funcName": "_resolve_lookup", "lineno": 933, "message": "Exception while resolving variable 'symbol' in template 'trading/orden_resultado.html'.", "exc_info": "Traceback (most recent call last):\n  File \"C:\\Users\\Eliana Galban\\AppData\\Local\\Programs\\Python\\Python312\\Lib\\site-packages\\django\\template\\base.py\", line 883, in _resolve_lookup\n    current = current[bit]\n              ~~~~~~~^^^^^\nKeyError: 'symbol'\n\nDuring handling of the above exception, another exception occurred:\n\nTraceback (most recent call last):\n  File \"C:\\Users\\Eliana Galban\\AppData\\Local\\Programs\\Python\\Python312\\Lib\\site-packages\\django\\template\\base.py\", line 893, in _resolve_lookup\n    current = getattr(current, bit)\n              ^^^^^^^^^^^^^^^^^^^^^\nAttributeError: 'dict' object has no attribute 'symbol'\n\nDuring handling of the above exception, another exception occurred:\n\nTraceback (most recent call last):\n  File \"C:\\Users\\Eliana Galban\\AppData\\Local\\Programs\\Python\\Python312\\Lib\\site-packages\\django\\template\\base.py\", line 899, in _resolve_lookup\n    current = current[int(bit)]\n                      ^^^^^^^^\nValueError: invalid literal for int() with base 10: 'symbol'\n\nDuring handling of the above exception, another exception occurred:\n\nTraceback (most recent call last):\n  File \"C:\\Users\\Eliana Galban\\AppData\\Local\\Programs\\Python\\Python312\\Lib\\site-packages\\django\\template\\base.py\", line 906, in _resolve_lookup\n    raise VariableDoesNotExist(\ndjango.template.base.VariableDoesNotExist: Failed lookup for key [symbol] in {'data': {'id': '6304a063-3f5b-48c2-a0f1-94b03fca150a', 'client_order_id': '12980e33-18c1-45b7-ac97-d86d7ded3661', 'created_at': '2025-05-23T10:53:05.017835192Z', 'updated_at': '2025-05-23T10:53:05.019181042Z', 'submitted_at': '2025-05-23T10:53:05.017835192Z', 'filled_at': None, 'expired_at': None, 'canceled_at': None, 'failed_at': None, 'replaced_at': None, 'replaced_by': None, 'replaces': None, 'asset_id': '0e967a96-2a81-4eaf-91cc-83d5cce69717', 'symbol': 'MRVI', 'asset_class': 'us_equity', 'notional': None, 'qty': '1', 'filled_qty': '0', 'filled_avg_price': None, 'order_class': '', 'order_type': 'market', 'type': 'market', 'side': 'buy', 'position_intent': 'buy_to_open', 'time_in_force': 'gtc', 'limit_price': None, 'stop_price': None, 'status': 'accepted', 'extended_hours': False, 'legs': None, 'trail_percent': None, 'trail_price': None, 'hwm': None, 'commission': '0', 'subtag': None, 'source': None, 'expires_at': '2025-08-21T20:00:00Z'}, 'order_id': '6304a063-3f5b-48c2-a0f1-94b03fca150a', 'status': 'accepted'}"}
{"asctime": "2025-05-23 06:03:18,387", "levelname": "DEBUG", "name": "django.template", "module": "base", "funcName": "_resolve_lookup", "lineno": 933, "message": "Exception while resolving variable 'error' in template 'trading/orden_resultado.html'.", "exc_info": "Traceback (most recent call last):\n  File \"C:\\Users\\Eliana Galban\\AppData\\Local\\Programs\\Python\\Python312\\Lib\\site-packages\\django\\template\\base.py\", line 883, in _resolve_lookup\n    current = current[bit]\n              ~~~~~~~^^^^^\nKeyError: 'error'\n\nDuring handling of the above exception, another exception occurred:\n\nTraceback (most recent call last):\n  File \"C:\\Users\\Eliana Galban\\AppData\\Local\\Programs\\Python\\Python312\\Lib\\site-packages\\django\\template\\base.py\", line 893, in _resolve_lookup\n    current = getattr(current, bit)\n              ^^^^^^^^^^^^^^^^^^^^^\nAttributeError: 'dict' object has no attribute 'error'\n\nDuring handling of the above exception, another exception occurred:\n\nTraceback (most recent call last):\n  File \"C:\\Users\\Eliana Galban\\AppData\\Local\\Programs\\Python\\Python312\\Lib\\site-packages\\django\\template\\base.py\", line 899, in _resolve_lookup\n    current = current[int(bit)]\n                      ^^^^^^^^\nValueError: invalid literal for int() with base 10: 'error'\n\nDuring handling of the above exception, another exception occurred:\n\nTraceback (most recent call last):\n  File \"C:\\Users\\Eliana Galban\\AppData\\Local\\Programs\\Python\\Python312\\Lib\\site-packages\\django\\template\\base.py\", line 906, in _resolve_lookup\n    raise VariableDoesNotExist(\ndjango.template.base.VariableDoesNotExist: Failed lookup for key [error] in {'data': {'id': '4c9afc6b-b2ea-47dc-bfed-165180b142cb', 'client_order_id': 'c33abbee-58ef-4f2f-8145-ec7c576ffea9', 'created_at': '2025-05-23T11:03:18.709987514Z', 'updated_at': '2025-05-23T11:03:18.711320954Z', 'submitted_at': '2025-05-23T11:03:18.709987514Z', 'filled_at': None, 'expired_at': None, 'canceled_at': None, 'failed_at': None, 'replaced_at': None, 'replaced_by': None, 'replaces': None, 'asset_id': '0e967a96-2a81-4eaf-91cc-83d5cce69717', 'symbol': 'MRVI', 'asset_class': 'us_equity', 'notional': None, 'qty': '2', 'filled_qty': '0', 'filled_avg_price': None, 'order_class': '', 'order_type': 'market', 'type': 'market', 'side': 'buy', 'position_intent': 'buy_to_open', 'time_in_force': 'gtc', 'limit_price': None, 'stop_price': None, 'status': 'pending_new', 'extended_hours': False, 'legs': None, 'trail_percent': None, 'trail_price': None, 'hwm': None, 'commission': '0', 'subtag': None, 'source': None, 'expires_at': '2025-08-21T20:00:00Z'}, 'order_id': '4c9afc6b-b2ea-47dc-bfed-165180b142cb', 'status': 'pending_new'}"}
{"asctime": "2025-05-23 06:03:18,389", "levelname": "DEBUG", "name": "django.template", "module": "base", "funcName": "_resolve_lookup", "lineno": 933, "message": "Exception while resolving variable 'symbol' in template 'trading/orden_resultado.html'.", "exc_info": "Traceback (most recent call last):\n  File \"C:\\Users\\Eliana Galban\\AppData\\Local\\Programs\\Python\\Python312\\Lib\\site-packages\\django\\template\\base.py\", line 883, in _resolve_lookup\n    current = current[bit]\n              ~~~~~~~^^^^^\nKeyError: 'symbol'\n\nDuring handling of the above exception, another exception occurred:\n\nTraceback (most recent call last):\n  File \"C:\\Users\\Eliana Galban\\AppData\\Local\\Programs\\Python\\Python312\\Lib\\site-packages\\django\\template\\base.py\", line 893, in _resolve_lookup\n    current = getattr(current, bit)\n              ^^^^^^^^^^^^^^^^^^^^^\nAttributeError: 'dict' object has no attribute 'symbol'\n\nDuring handling of the above exception, another exception occurred:\n\nTraceback (most recent call last):\n  File \"C:\\Users\\Eliana Galban\\AppData\\Local\\Programs\\Python\\Python312\\Lib\\site-packages\\django\\template\\base.py\", line 899, in _resolve_lookup\n    current = current[int(bit)]\n                      ^^^^^^^^\nValueError: invalid literal for int() with base 10: 'symbol'\n\nDuring handling of the above exception, another exception occurred:\n\nTraceback (most recent call last):\n  File \"C:\\Users\\Eliana Galban\\AppData\\Local\\Programs\\Python\\Python312\\Lib\\site-packages\\django\\template\\base.py\", line 906, in _resolve_lookup\n    raise VariableDoesNotExist(\ndjango.template.base.VariableDoesNotExist: Failed lookup for key [symbol] in {'data': {'id': '4c9afc6b-b2ea-47dc-bfed-165180b142cb', 'client_order_id': 'c33abbee-58ef-4f2f-8145-ec7c576ffea9', 'created_at': '2025-05-23T11:03:18.709987514Z', 'updated_at': '2025-05-23T11:03:18.711320954Z', 'submitted_at': '2025-05-23T11:03:18.709987514Z', 'filled_at': None, 'expired_at': None, 'canceled_at': None, 'failed_at': None, 'replaced_at': None, 'replaced_by': None, 'replaces': None, 'asset_id': '0e967a96-2a81-4eaf-91cc-83d5cce69717', 'symbol': 'MRVI', 'asset_class': 'us_equity', 'notional': None, 'qty': '2', 'filled_qty': '0', 'filled_avg_price': None, 'order_class': '', 'order_type': 'market', 'type': 'market', 'side': 'buy', 'position_intent': 'buy_to_open', 'time_in_force': 'gtc', 'limit_price': None, 'stop_price': None, 'status': 'pending_new', 'extended_hours': False, 'legs': None, 'trail_percent': None, 'trail_price': None, 'hwm': None, 'commission': '0', 'subtag': None, 'source': None, 'expires_at': '2025-08-21T20:00:00Z'}, 'order_id': '4c9afc6b-b2ea-47dc-bfed-165180b142cb', 'status': 'pending_new'}"}
{"asctime": "2025-05-23 06:05:42,963", "levelname": "DEBUG", "name": "django.template", "module": "base", "funcName": "_resolve_lookup", "lineno": 933, "message": "Exception while resolving variable 'error' in template 'trading/orden_resultado.html'.", "exc_info": "Traceback (most recent call last):\n  File \"C:\\Users\\Eliana Galban\\AppData\\Local\\Programs\\Python\\Python312\\Lib\\site-packages\\django\\template\\base.py\", line 883, in _resolve_lookup\n    current = current[bit]\n              ~~~~~~~^^^^^\nKeyError: 'error'\n\nDuring handling of the above exception, another exception occurred:\n\nTraceback (most recent call last):\n  File \"C:\\Users\\Eliana Galban\\AppData\\Local\\Programs\\Python\\Python312\\Lib\\site-packages\\django\\template\\base.py\", line 893, in _resolve_lookup\n    current = getattr(current, bit)\n              ^^^^^^^^^^^^^^^^^^^^^\nAttributeError: 'dict' object has no attribute 'error'\n\nDuring handling of the above exception, another exception occurred:\n\nTraceback (most recent call last):\n  File \"C:\\Users\\Eliana Galban\\AppData\\Local\\Programs\\Python\\Python312\\Lib\\site-packages\\django\\template\\base.py\", line 899, in _resolve_lookup\n    current = current[int(bit)]\n                      ^^^^^^^^\nValueError: invalid literal for int() with base 10: 'error'\n\nDuring handling of the above exception, another exception occurred:\n\nTraceback (most recent call last):\n  File \"C:\\Users\\Eliana Galban\\AppData\\Local\\Programs\\Python\\Python312\\Lib\\site-packages\\django\\template\\base.py\", line 906, in _resolve_lookup\n    raise VariableDoesNotExist(\ndjango.template.base.VariableDoesNotExist: Failed lookup for key [error] in {'data': {'id': 'ee0cde4a-6205-42e9-8b2a-ba78844eb10e', 'client_order_id': 'c7b51d96-719f-42d1-a825-49b5d672a956', 'created_at': '2025-05-23T11:05:43.288299462Z', 'updated_at': '2025-05-23T11:05:43.290515272Z', 'submitted_at': '2025-05-23T11:05:43.288299462Z', 'filled_at': None, 'expired_at': None, 'canceled_at': None, 'failed_at': None, 'replaced_at': None, 'replaced_by': None, 'replaces': None, 'asset_id': '0e967a96-2a81-4eaf-91cc-83d5cce69717', 'symbol': 'MRVI', 'asset_class': 'us_equity', 'notional': None, 'qty': '2', 'filled_qty': '0', 'filled_avg_price': None, 'order_class': '', 'order_type': 'market', 'type': 'market', 'side': 'buy', 'position_intent': 'buy_to_open', 'time_in_force': 'gtc', 'limit_price': None, 'stop_price': None, 'status': 'pending_new', 'extended_hours': False, 'legs': None, 'trail_percent': None, 'trail_price': None, 'hwm': None, 'commission': '0', 'subtag': None, 'source': None, 'expires_at': '2025-08-21T20:00:00Z'}, 'order_id': 'ee0cde4a-6205-42e9-8b2a-ba78844eb10e', 'status': 'pending_new'}"}
{"asctime": "2025-05-23 06:05:42,965", "levelname": "DEBUG", "name": "django.template", "module": "base", "funcName": "_resolve_lookup", "lineno": 933, "message": "Exception while resolving variable 'symbol' in template 'trading/orden_resultado.html'.", "exc_info": "Traceback (most recent call last):\n  File \"C:\\Users\\Eliana Galban\\AppData\\Local\\Programs\\Python\\Python312\\Lib\\site-packages\\django\\template\\base.py\", line 883, in _resolve_lookup\n    current = current[bit]\n              ~~~~~~~^^^^^\nKeyError: 'symbol'\n\nDuring handling of the above exception, another exception occurred:\n\nTraceback (most recent call last):\n  File \"C:\\Users\\Eliana Galban\\AppData\\Local\\Programs\\Python\\Python312\\Lib\\site-packages\\django\\template\\base.py\", line 893, in _resolve_lookup\n    current = getattr(current, bit)\n              ^^^^^^^^^^^^^^^^^^^^^\nAttributeError: 'dict' object has no attribute 'symbol'\n\nDuring handling of the above exception, another exception occurred:\n\nTraceback (most recent call last):\n  File \"C:\\Users\\Eliana Galban\\AppData\\Local\\Programs\\Python\\Python312\\Lib\\site-packages\\django\\template\\base.py\", line 899, in _resolve_lookup\n    current = current[int(bit)]\n                      ^^^^^^^^\nValueError: invalid literal for int() with base 10: 'symbol'\n\nDuring handling of the above exception, another exception occurred:\n\nTraceback (most recent call last):\n  File \"C:\\Users\\Eliana Galban\\AppData\\Local\\Programs\\Python\\Python312\\Lib\\site-packages\\django\\template\\base.py\", line 906, in _resolve_lookup\n    raise VariableDoesNotExist(\ndjango.template.base.VariableDoesNotExist: Failed lookup for key [symbol] in {'data': {'id': 'ee0cde4a-6205-42e9-8b2a-ba78844eb10e', 'client_order_id': 'c7b51d96-719f-42d1-a825-49b5d672a956', 'created_at': '2025-05-23T11:05:43.288299462Z', 'updated_at': '2025-05-23T11:05:43.290515272Z', 'submitted_at': '2025-05-23T11:05:43.288299462Z', 'filled_at': None, 'expired_at': None, 'canceled_at': None, 'failed_at': None, 'replaced_at': None, 'replaced_by': None, 'replaces': None, 'asset_id': '0e967a96-2a81-4eaf-91cc-83d5cce69717', 'symbol': 'MRVI', 'asset_class': 'us_equity', 'notional': None, 'qty': '2', 'filled_qty': '0', 'filled_avg_price': None, 'order_class': '', 'order_type': 'market', 'type': 'market', 'side': 'buy', 'position_intent': 'buy_to_open', 'time_in_force': 'gtc', 'limit_price': None, 'stop_price': None, 'status': 'pending_new', 'extended_hours': False, 'legs': None, 'trail_percent': None, 'trail_price': None, 'hwm': None, 'commission': '0', 'subtag': None, 'source': None, 'expires_at': '2025-08-21T20:00:00Z'}, 'order_id': 'ee0cde4a-6205-42e9-8b2a-ba78844eb10e', 'status': 'pending_new'}"}
{"asctime": "2025-05-23 06:06:39,787", "levelname": "DEBUG", "name": "django.template", "module": "base", "funcName": "_resolve_lookup", "lineno": 933, "message": "Exception while resolving variable 'error' in template 'trading/orden_resultado.html'.", "exc_info": "Traceback (most recent call last):\n  File \"C:\\Users\\Eliana Galban\\AppData\\Local\\Programs\\Python\\Python312\\Lib\\site-packages\\django\\template\\base.py\", line 883, in _resolve_lookup\n    current = current[bit]\n              ~~~~~~~^^^^^\nKeyError: 'error'\n\nDuring handling of the above exception, another exception occurred:\n\nTraceback (most recent call last):\n  File \"C:\\Users\\Eliana Galban\\AppData\\Local\\Programs\\Python\\Python312\\Lib\\site-packages\\django\\template\\base.py\", line 893, in _resolve_lookup\n    current = getattr(current, bit)\n              ^^^^^^^^^^^^^^^^^^^^^\nAttributeError: 'dict' object has no attribute 'error'\n\nDuring handling of the above exception, another exception occurred:\n\nTraceback (most recent call last):\n  File \"C:\\Users\\Eliana Galban\\AppData\\Local\\Programs\\Python\\Python312\\Lib\\site-packages\\django\\template\\base.py\", line 899, in _resolve_lookup\n    current = current[int(bit)]\n                      ^^^^^^^^\nValueError: invalid literal for int() with base 10: 'error'\n\nDuring handling of the above exception, another exception occurred:\n\nTraceback (most recent call last):\n  File \"C:\\Users\\Eliana Galban\\AppData\\Local\\Programs\\Python\\Python312\\Lib\\site-packages\\django\\template\\base.py\", line 906, in _resolve_lookup\n    raise VariableDoesNotExist(\ndjango.template.base.VariableDoesNotExist: Failed lookup for key [error] in {'data': {'id': '2513f8e6-0831-44fe-bfe2-496abba8ea3b', 'client_order_id': '84890ebe-bde6-4c93-936a-d0b2592ba660', 'created_at': '2025-05-23T11:06:40.11738378Z', 'updated_at': '2025-05-23T11:06:40.119216849Z', 'submitted_at': '2025-05-23T11:06:40.11738378Z', 'filled_at': None, 'expired_at': None, 'canceled_at': None, 'failed_at': None, 'replaced_at': None, 'replaced_by': None, 'replaces': None, 'asset_id': 'd4662f45-0d9d-43fb-bec6-137f43eaa473', 'symbol': 'MSBI', 'asset_class': 'us_equity', 'notional': None, 'qty': '1', 'filled_qty': '0', 'filled_avg_price': None, 'order_class': '', 'order_type': 'market', 'type': 'market', 'side': 'buy', 'position_intent': 'buy_to_open', 'time_in_force': 'gtc', 'limit_price': None, 'stop_price': None, 'status': 'pending_new', 'extended_hours': False, 'legs': None, 'trail_percent': None, 'trail_price': None, 'hwm': None, 'commission': '0', 'subtag': None, 'source': None, 'expires_at': '2025-08-21T20:00:00Z'}, 'order_id': '2513f8e6-0831-44fe-bfe2-496abba8ea3b', 'status': 'pending_new'}"}
{"asctime": "2025-05-23 06:06:39,789", "levelname": "DEBUG", "name": "django.template", "module": "base", "funcName": "_resolve_lookup", "lineno": 933, "message": "Exception while resolving variable 'symbol' in template 'trading/orden_resultado.html'.", "exc_info": "Traceback (most recent call last):\n  File \"C:\\Users\\Eliana Galban\\AppData\\Local\\Programs\\Python\\Python312\\Lib\\site-packages\\django\\template\\base.py\", line 883, in _resolve_lookup\n    current = current[bit]\n              ~~~~~~~^^^^^\nKeyError: 'symbol'\n\nDuring handling of the above exception, another exception occurred:\n\nTraceback (most recent call last):\n  File \"C:\\Users\\Eliana Galban\\AppData\\Local\\Programs\\Python\\Python312\\Lib\\site-packages\\django\\template\\base.py\", line 893, in _resolve_lookup\n    current = getattr(current, bit)\n              ^^^^^^^^^^^^^^^^^^^^^\nAttributeError: 'dict' object has no attribute 'symbol'\n\nDuring handling of the above exception, another exception occurred:\n\nTraceback (most recent call last):\n  File \"C:\\Users\\Eliana Galban\\AppData\\Local\\Programs\\Python\\Python312\\Lib\\site-packages\\django\\template\\base.py\", line 899, in _resolve_lookup\n    current = current[int(bit)]\n                      ^^^^^^^^\nValueError: invalid literal for int() with base 10: 'symbol'\n\nDuring handling of the above exception, another exception occurred:\n\nTraceback (most recent call last):\n  File \"C:\\Users\\Eliana Galban\\AppData\\Local\\Programs\\Python\\Python312\\Lib\\site-packages\\django\\template\\base.py\", line 906, in _resolve_lookup\n    raise VariableDoesNotExist(\ndjango.template.base.VariableDoesNotExist: Failed lookup for key [symbol] in {'data': {'id': '2513f8e6-0831-44fe-bfe2-496abba8ea3b', 'client_order_id': '84890ebe-bde6-4c93-936a-d0b2592ba660', 'created_at': '2025-05-23T11:06:40.11738378Z', 'updated_at': '2025-05-23T11:06:40.119216849Z', 'submitted_at': '2025-05-23T11:06:40.11738378Z', 'filled_at': None, 'expired_at': None, 'canceled_at': None, 'failed_at': None, 'replaced_at': None, 'replaced_by': None, 'replaces': None, 'asset_id': 'd4662f45-0d9d-43fb-bec6-137f43eaa473', 'symbol': 'MSBI', 'asset_class': 'us_equity', 'notional': None, 'qty': '1', 'filled_qty': '0', 'filled_avg_price': None, 'order_class': '', 'order_type': 'market', 'type': 'market', 'side': 'buy', 'position_intent': 'buy_to_open', 'time_in_force': 'gtc', 'limit_price': None, 'stop_price': None, 'status': 'pending_new', 'extended_hours': False, 'legs': None, 'trail_percent': None, 'trail_price': None, 'hwm': None, 'commission': '0', 'subtag': None, 'source': None, 'expires_at': '2025-08-21T20:00:00Z'}, 'order_id': '2513f8e6-0831-44fe-bfe2-496abba8ea3b', 'status': 'pending_new'}"}
{"asctime": "2025-05-23 06:12:56,125", "levelname": "DEBUG", "name": "django.template", "module": "base", "funcName": "_resolve_lookup", "lineno": 933, "message": "Exception while resolving variable 'error' in template 'trading/orden_resultado.html'.", "exc_info": "Traceback (most recent call last):\n  File \"C:\\Users\\Eliana Galban\\AppData\\Local\\Programs\\Python\\Python312\\Lib\\site-packages\\django\\template\\base.py\", line 883, in _resolve_lookup\n    current = current[bit]\n              ~~~~~~~^^^^^\nKeyError: 'error'\n\nDuring handling of the above exception, another exception occurred:\n\nTraceback (most recent call last):\n  File \"C:\\Users\\Eliana Galban\\AppData\\Local\\Programs\\Python\\Python312\\Lib\\site-packages\\django\\template\\base.py\", line 893, in _resolve_lookup\n    current = getattr(current, bit)\n              ^^^^^^^^^^^^^^^^^^^^^\nAttributeError: 'dict' object has no attribute 'error'\n\nDuring handling of the above exception, another exception occurred:\n\nTraceback (most recent call last):\n  File \"C:\\Users\\Eliana Galban\\AppData\\Local\\Programs\\Python\\Python312\\Lib\\site-packages\\django\\template\\base.py\", line 899, in _resolve_lookup\n    current = current[int(bit)]\n                      ^^^^^^^^\nValueError: invalid literal for int() with base 10: 'error'\n\nDuring handling of the above exception, another exception occurred:\n\nTraceback (most recent call last):\n  File \"C:\\Users\\Eliana Galban\\AppData\\Local\\Programs\\Python\\Python312\\Lib\\site-packages\\django\\template\\base.py\", line 906, in _resolve_lookup\n    raise VariableDoesNotExist(\ndjango.template.base.VariableDoesNotExist: Failed lookup for key [error] in {'data': {'id': '1998f755-dd20-448f-a9d8-7d0ce7eae72d', 'client_order_id': 'e796ec0e-b6eb-41ad-8baf-43f3a861e35e', 'created_at': '2025-05-23T11:12:56.445944411Z', 'updated_at': '2025-05-23T11:12:56.44846741Z', 'submitted_at': '2025-05-23T11:12:56.445944411Z', 'filled_at': None, 'expired_at': None, 'canceled_at': None, 'failed_at': None, 'replaced_at': None, 'replaced_by': None, 'replaces': None, 'asset_id': '0e967a96-2a81-4eaf-91cc-83d5cce69717', 'symbol': 'MRVI', 'asset_class': 'us_equity', 'notional': None, 'qty': '1', 'filled_qty': '0', 'filled_avg_price': None, 'order_class': '', 'order_type': 'market', 'type': 'market', 'side': 'buy', 'position_intent': 'buy_to_open', 'time_in_force': 'gtc', 'limit_price': None, 'stop_price': None, 'status': 'pending_new', 'extended_hours': False, 'legs': None, 'trail_percent': None, 'trail_price': None, 'hwm': None, 'commission': '0', 'subtag': None, 'source': None, 'expires_at': '2025-08-21T20:00:00Z'}, 'order_id': '1998f755-dd20-448f-a9d8-7d0ce7eae72d', 'status': 'pending_new'}"}
{"asctime": "2025-05-23 06:12:56,129", "levelname": "DEBUG", "name": "django.template", "module": "base", "funcName": "_resolve_lookup", "lineno": 933, "message": "Exception while resolving variable 'qty' in template 'trading/orden_resultado.html'.", "exc_info": "Traceback (most recent call last):\n  File \"C:\\Users\\Eliana Galban\\AppData\\Local\\Programs\\Python\\Python312\\Lib\\site-packages\\django\\template\\base.py\", line 883, in _resolve_lookup\n    current = current[bit]\n              ~~~~~~~^^^^^\nKeyError: 'qty'\n\nDuring handling of the above exception, another exception occurred:\n\nTraceback (most recent call last):\n  File \"C:\\Users\\Eliana Galban\\AppData\\Local\\Programs\\Python\\Python312\\Lib\\site-packages\\django\\template\\base.py\", line 893, in _resolve_lookup\n    current = getattr(current, bit)\n              ^^^^^^^^^^^^^^^^^^^^^\nAttributeError: 'dict' object has no attribute 'qty'\n\nDuring handling of the above exception, another exception occurred:\n\nTraceback (most recent call last):\n  File \"C:\\Users\\Eliana Galban\\AppData\\Local\\Programs\\Python\\Python312\\Lib\\site-packages\\django\\template\\base.py\", line 899, in _resolve_lookup\n    current = current[int(bit)]\n                      ^^^^^^^^\nValueError: invalid literal for int() with base 10: 'qty'\n\nDuring handling of the above exception, another exception occurred:\n\nTraceback (most recent call last):\n  File \"C:\\Users\\Eliana Galban\\AppData\\Local\\Programs\\Python\\Python312\\Lib\\site-packages\\django\\template\\base.py\", line 906, in _resolve_lookup\n    raise VariableDoesNotExist(\ndjango.template.base.VariableDoesNotExist: Failed lookup for key [qty] in {'data': {'id': '1998f755-dd20-448f-a9d8-7d0ce7eae72d', 'client_order_id': 'e796ec0e-b6eb-41ad-8baf-43f3a861e35e', 'created_at': '2025-05-23T11:12:56.445944411Z', 'updated_at': '2025-05-23T11:12:56.44846741Z', 'submitted_at': '2025-05-23T11:12:56.445944411Z', 'filled_at': None, 'expired_at': None, 'canceled_at': None, 'failed_at': None, 'replaced_at': None, 'replaced_by': None, 'replaces': None, 'asset_id': '0e967a96-2a81-4eaf-91cc-83d5cce69717', 'symbol': 'MRVI', 'asset_class': 'us_equity', 'notional': None, 'qty': '1', 'filled_qty': '0', 'filled_avg_price': None, 'order_class': '', 'order_type': 'market', 'type': 'market', 'side': 'buy', 'position_intent': 'buy_to_open', 'time_in_force': 'gtc', 'limit_price': None, 'stop_price': None, 'status': 'pending_new', 'extended_hours': False, 'legs': None, 'trail_percent': None, 'trail_price': None, 'hwm': None, 'commission': '0', 'subtag': None, 'source': None, 'expires_at': '2025-08-21T20:00:00Z'}, 'order_id': '1998f755-dd20-448f-a9d8-7d0ce7eae72d', 'status': 'pending_new'}"}
{"asctime": "2025-05-23 06:22:58,464", "levelname": "DEBUG", "name": "django.template", "module": "base", "funcName": "_resolve_lookup", "lineno": 933, "message": "Exception while resolving variable 'symbol_prefill' in template 'trading/comprar.html'.", "exc_info": "Traceback (most recent call last):\n  File \"C:\\Users\\Eliana Galban\\AppData\\Local\\Programs\\Python\\Python312\\Lib\\site-packages\\django\\template\\base.py\", line 883, in _resolve_lookup\n    current = current[bit]\n              ~~~~~~~^^^^^\n  File \"C:\\Users\\Eliana Galban\\AppData\\Local\\Programs\\Python\\Python312\\Lib\\site-packages\\django\\template\\context.py\", line 85, in __getitem__\n    raise KeyError(key)\nKeyError: 'symbol_prefill'\n\nDuring handling of the above exception, another exception occurred:\n\nTraceback (most recent call last):\n  File \"C:\\Users\\Eliana Galban\\AppData\\Local\\Programs\\Python\\Python312\\Lib\\site-packages\\django\\template\\base.py\", line 889, in _resolve_lookup\n    if isinstance(current, BaseContext) and getattr(\n                                            ^^^^^^^^\nAttributeError: type object 'RequestContext' has no attribute 'symbol_prefill'\n\nDuring handling of the above exception, another exception occurred:\n\nTraceback (most recent call last):\n  File \"C:\\Users\\Eliana Galban\\AppData\\Local\\Programs\\Python\\Python312\\Lib\\site-packages\\django\\template\\base.py\", line 899, in _resolve_lookup\n    current = current[int(bit)]\n                      ^^^^^^^^\nValueError: invalid literal for int() with base 10: 'symbol_prefill'\n\nDuring handling of the above exception, another exception occurred:\n\nTraceback (most recent call last):\n  File \"C:\\Users\\Eliana Galban\\AppData\\Local\\Programs\\Python\\Python312\\Lib\\site-packages\\django\\template\\base.py\", line 906, in _resolve_lookup\n    raise VariableDoesNotExist(\ndjango.template.base.VariableDoesNotExist: Failed lookup for key [symbol_prefill] in [{'True': True, 'False': False, 'None': None}, {'csrf_token': <SimpleLazyObject: 'T7gHFP3jCPpa2EIy3ApPlCMzW1DECmkZ70ne7jiEvkO73AyOFZjk5eLgHu5qa9GC'>, 'request': <WSGIRequest: GET '/trading/comprar/?symbol=MRVI'>, 'user': <SimpleLazyObject: <function AuthenticationMiddleware.process_request.<locals>.<lambda> at 0x0000022C40E9D080>>, 'perms': PermWrapper(<SimpleLazyObject: <function AuthenticationMiddleware.process_request.<locals>.<lambda> at 0x0000022C40E9D080>>), 'messages': <FallbackStorage: request=<WSGIRequest: GET '/trading/comprar/?symbol=MRVI'>>, 'DEFAULT_MESSAGE_LEVELS': {'DEBUG': 10, 'INFO': 20, 'SUCCESS': 25, 'WARNING': 30, 'ERROR': 40}}, {}]"}
{"asctime": "2025-05-23 06:23:11,197", "levelname": "DEBUG", "name": "django.template", "module": "base", "funcName": "_resolve_lookup", "lineno": 933, "message": "Exception while resolving variable 'error' in template 'trading/orden_resultado.html'.", "exc_info": "Traceback (most recent call last):\n  File \"C:\\Users\\Eliana Galban\\AppData\\Local\\Programs\\Python\\Python312\\Lib\\site-packages\\django\\template\\base.py\", line 883, in _resolve_lookup\n    current = current[bit]\n              ~~~~~~~^^^^^\nKeyError: 'error'\n\nDuring handling of the above exception, another exception occurred:\n\nTraceback (most recent call last):\n  File \"C:\\Users\\Eliana Galban\\AppData\\Local\\Programs\\Python\\Python312\\Lib\\site-packages\\django\\template\\base.py\", line 893, in _resolve_lookup\n    current = getattr(current, bit)\n              ^^^^^^^^^^^^^^^^^^^^^\nAttributeError: 'dict' object has no attribute 'error'\n\nDuring handling of the above exception, another exception occurred:\n\nTraceback (most recent call last):\n  File \"C:\\Users\\Eliana Galban\\AppData\\Local\\Programs\\Python\\Python312\\Lib\\site-packages\\django\\template\\base.py\", line 899, in _resolve_lookup\n    current = current[int(bit)]\n                      ^^^^^^^^\nValueError: invalid literal for int() with base 10: 'error'\n\nDuring handling of the above exception, another exception occurred:\n\nTraceback (most recent call last):\n  File \"C:\\Users\\Eliana Galban\\AppData\\Local\\Programs\\Python\\Python312\\Lib\\site-packages\\django\\template\\base.py\", line 906, in _resolve_lookup\n    raise VariableDoesNotExist(\ndjango.template.base.VariableDoesNotExist: Failed lookup for key [error] in {'data': {'id': 'b34715c7-22bc-4eaa-981d-8ca6b77aa8c4', 'client_order_id': 'e8ea75ac-911e-4403-823e-38d4e2703e55', 'created_at': '2025-05-23T11:23:11.454206435Z', 'updated_at': '2025-05-23T11:23:11.456247875Z', 'submitted_at': '2025-05-23T11:23:11.454206435Z', 'filled_at': None, 'expired_at': None, 'canceled_at': None, 'failed_at': None, 'replaced_at': None, 'replaced_by': None, 'replaces': None, 'asset_id': '0e967a96-2a81-4eaf-91cc-83d5cce69717', 'symbol': 'MRVI', 'asset_class': 'us_equity', 'notional': None, 'qty': '1', 'filled_qty': '0', 'filled_avg_price': None, 'order_class': '', 'order_type': 'market', 'type': 'market', 'side': 'buy', 'position_intent': 'buy_to_open', 'time_in_force': 'gtc', 'limit_price': None, 'stop_price': None, 'status': 'pending_new', 'extended_hours': False, 'legs': None, 'trail_percent': None, 'trail_price': None, 'hwm': None, 'commission': '0', 'subtag': None, 'source': None, 'expires_at': '2025-08-21T20:00:00Z'}, 'order_id': 'b34715c7-22bc-4eaa-981d-8ca6b77aa8c4', 'status': 'pending_new'}"}
{"asctime": "2025-05-23 06:23:11,199", "levelname": "DEBUG", "name": "django.template", "module": "base", "funcName": "_resolve_lookup", "lineno": 933, "message": "Exception while resolving variable 'qty' in template 'trading/orden_resultado.html'.", "exc_info": "Traceback (most recent call last):\n  File \"C:\\Users\\Eliana Galban\\AppData\\Local\\Programs\\Python\\Python312\\Lib\\site-packages\\django\\template\\base.py\", line 883, in _resolve_lookup\n    current = current[bit]\n              ~~~~~~~^^^^^\nKeyError: 'qty'\n\nDuring handling of the above exception, another exception occurred:\n\nTraceback (most recent call last):\n  File \"C:\\Users\\Eliana Galban\\AppData\\Local\\Programs\\Python\\Python312\\Lib\\site-packages\\django\\template\\base.py\", line 893, in _resolve_lookup\n    current = getattr(current, bit)\n              ^^^^^^^^^^^^^^^^^^^^^\nAttributeError: 'dict' object has no attribute 'qty'\n\nDuring handling of the above exception, another exception occurred:\n\nTraceback (most recent call last):\n  File \"C:\\Users\\Eliana Galban\\AppData\\Local\\Programs\\Python\\Python312\\Lib\\site-packages\\django\\template\\base.py\", line 899, in _resolve_lookup\n    current = current[int(bit)]\n                      ^^^^^^^^\nValueError: invalid literal for int() with base 10: 'qty'\n\nDuring handling of the above exception, another exception occurred:\n\nTraceback (most recent call last):\n  File \"C:\\Users\\Eliana Galban\\AppData\\Local\\Programs\\Python\\Python312\\Lib\\site-packages\\django\\template\\base.py\", line 906, in _resolve_lookup\n    raise VariableDoesNotExist(\ndjango.template.base.VariableDoesNotExist: Failed lookup for key [qty] in {'data': {'id': 'b34715c7-22bc-4eaa-981d-8ca6b77aa8c4', 'client_order_id': 'e8ea75ac-911e-4403-823e-38d4e2703e55', 'created_at': '2025-05-23T11:23:11.454206435Z', 'updated_at': '2025-05-23T11:23:11.456247875Z', 'submitted_at': '2025-05-23T11:23:11.454206435Z', 'filled_at': None, 'expired_at': None, 'canceled_at': None, 'failed_at': None, 'replaced_at': None, 'replaced_by': None, 'replaces': None, 'asset_id': '0e967a96-2a81-4eaf-91cc-83d5cce69717', 'symbol': 'MRVI', 'asset_class': 'us_equity', 'notional': None, 'qty': '1', 'filled_qty': '0', 'filled_avg_price': None, 'order_class': '', 'order_type': 'market', 'type': 'market', 'side': 'buy', 'position_intent': 'buy_to_open', 'time_in_force': 'gtc', 'limit_price': None, 'stop_price': None, 'status': 'pending_new', 'extended_hours': False, 'legs': None, 'trail_percent': None, 'trail_price': None, 'hwm': None, 'commission': '0', 'subtag': None, 'source': None, 'expires_at': '2025-08-21T20:00:00Z'}, 'order_id': 'b34715c7-22bc-4eaa-981d-8ca6b77aa8c4', 'status': 'pending_new'}"}
{"asctime": "2025-05-23 06:50:40,334", "levelname": "DEBUG", "name": "django.template", "module": "base", "funcName": "_resolve_lookup", "lineno": 933, "message": "Exception while resolving variable 'error' in template 'trading/orden_resultado.html'.", "exc_info": "Traceback (most recent call last):\n  File \"C:\\Users\\Eliana Galban\\AppData\\Local\\Programs\\Python\\Python312\\Lib\\site-packages\\django\\template\\base.py\", line 883, in _resolve_lookup\n    current = current[bit]\n              ~~~~~~~^^^^^\nKeyError: 'error'\n\nDuring handling of the above exception, another exception occurred:\n\nTraceback (most recent call last):\n  File \"C:\\Users\\Eliana Galban\\AppData\\Local\\Programs\\Python\\Python312\\Lib\\site-packages\\django\\template\\base.py\", line 893, in _resolve_lookup\n    current = getattr(current, bit)\n              ^^^^^^^^^^^^^^^^^^^^^\nAttributeError: 'dict' object has no attribute 'error'\n\nDuring handling of the above exception, another exception occurred:\n\nTraceback (most recent call last):\n  File \"C:\\Users\\Eliana Galban\\AppData\\Local\\Programs\\Python\\Python312\\Lib\\site-packages\\django\\template\\base.py\", line 899, in _resolve_lookup\n    current = current[int(bit)]\n                      ^^^^^^^^\nValueError: invalid literal for int() with base 10: 'error'\n\nDuring handling of the above exception, another exception occurred:\n\nTraceback (most recent call last):\n  File \"C:\\Users\\Eliana Galban\\AppData\\Local\\Programs\\Python\\Python312\\Lib\\site-packages\\django\\template\\base.py\", line 906, in _resolve_lookup\n    raise VariableDoesNotExist(\ndjango.template.base.VariableDoesNotExist: Failed lookup for key [error] in {'data': {'id': '5963f538-c77a-496a-9e50-fea15a534a7d', 'client_order_id': 'b8bd4f31-10f6-4f60-a304-730b6ab7ccfe', 'created_at': '2025-05-23T11:50:40.681910815Z', 'updated_at': '2025-05-23T11:50:40.684785074Z', 'submitted_at': '2025-05-23T11:50:40.681910815Z', 'filled_at': None, 'expired_at': None, 'canceled_at': None, 'failed_at': None, 'replaced_at': None, 'replaced_by': None, 'replaces': None, 'asset_id': '0e967a96-2a81-4eaf-91cc-83d5cce69717', 'symbol': 'MRVI', 'asset_class': 'us_equity', 'notional': None, 'qty': '1', 'filled_qty': '0', 'filled_avg_price': None, 'order_class': '', 'order_type': 'market', 'type': 'market', 'side': 'buy', 'position_intent': 'buy_to_open', 'time_in_force': 'gtc', 'limit_price': None, 'stop_price': None, 'status': 'pending_new', 'extended_hours': False, 'legs': None, 'trail_percent': None, 'trail_price': None, 'hwm': None, 'commission': '0', 'subtag': None, 'source': None, 'expires_at': '2025-08-21T20:00:00Z'}, 'order_id': '5963f538-c77a-496a-9e50-fea15a534a7d', 'status': 'pending_new'}"}
{"asctime": "2025-05-23 06:50:40,513", "levelname": "DEBUG", "name": "django.template", "module": "base", "funcName": "_resolve_lookup", "lineno": 933, "message": "Exception while resolving variable 'qty' in template 'trading/orden_resultado.html'.", "exc_info": "Traceback (most recent call last):\n  File \"C:\\Users\\Eliana Galban\\AppData\\Local\\Programs\\Python\\Python312\\Lib\\site-packages\\django\\template\\base.py\", line 883, in _resolve_lookup\n    current = current[bit]\n              ~~~~~~~^^^^^\nKeyError: 'qty'\n\nDuring handling of the above exception, another exception occurred:\n\nTraceback (most recent call last):\n  File \"C:\\Users\\Eliana Galban\\AppData\\Local\\Programs\\Python\\Python312\\Lib\\site-packages\\django\\template\\base.py\", line 893, in _resolve_lookup\n    current = getattr(current, bit)\n              ^^^^^^^^^^^^^^^^^^^^^\nAttributeError: 'dict' object has no attribute 'qty'\n\nDuring handling of the above exception, another exception occurred:\n\nTraceback (most recent call last):\n  File \"C:\\Users\\Eliana Galban\\AppData\\Local\\Programs\\Python\\Python312\\Lib\\site-packages\\django\\template\\base.py\", line 899, in _resolve_lookup\n    current = current[int(bit)]\n                      ^^^^^^^^\nValueError: invalid literal for int() with base 10: 'qty'\n\nDuring handling of the above exception, another exception occurred:\n\nTraceback (most recent call last):\n  File \"C:\\Users\\Eliana Galban\\AppData\\Local\\Programs\\Python\\Python312\\Lib\\site-packages\\django\\template\\base.py\", line 906, in _resolve_lookup\n    raise VariableDoesNotExist(\ndjango.template.base.VariableDoesNotExist: Failed lookup for key [qty] in {'data': {'id': '5963f538-c77a-496a-9e50-fea15a534a7d', 'client_order_id': 'b8bd4f31-10f6-4f60-a304-730b6ab7ccfe', 'created_at': '2025-05-23T11:50:40.681910815Z', 'updated_at': '2025-05-23T11:50:40.684785074Z', 'submitted_at': '2025-05-23T11:50:40.681910815Z', 'filled_at': None, 'expired_at': None, 'canceled_at': None, 'failed_at': None, 'replaced_at': None, 'replaced_by': None, 'replaces': None, 'asset_id': '0e967a96-2a81-4eaf-91cc-83d5cce69717', 'symbol': 'MRVI', 'asset_class': 'us_equity', 'notional': None, 'qty': '1', 'filled_qty': '0', 'filled_avg_price': None, 'order_class': '', 'order_type': 'market', 'type': 'market', 'side': 'buy', 'position_intent': 'buy_to_open', 'time_in_force': 'gtc', 'limit_price': None, 'stop_price': None, 'status': 'pending_new', 'extended_hours': False, 'legs': None, 'trail_percent': None, 'trail_price': None, 'hwm': None, 'commission': '0', 'subtag': None, 'source': None, 'expires_at': '2025-08-21T20:00:00Z'}, 'order_id': '5963f538-c77a-496a-9e50-fea15a534a7d', 'status': 'pending_new'}"}
{"asctime": "2025-05-23 07:00:17,304", "levelname": "DEBUG", "name": "django.template", "module": "base", "funcName": "_resolve_lookup", "lineno": 933, "message": "Exception while resolving variable 'symbol' in template 'trading/orden_resultado.html'.", "exc_info": "Traceback (most recent call last):\n  File \"C:\\Users\\Eliana Galban\\AppData\\Local\\Programs\\Python\\Python312\\Lib\\site-packages\\django\\template\\base.py\", line 883, in _resolve_lookup\n    current = current[bit]\n              ~~~~~~~^^^^^\nKeyError: 'symbol'\n\nDuring handling of the above exception, another exception occurred:\n\nTraceback (most recent call last):\n  File \"C:\\Users\\Eliana Galban\\AppData\\Local\\Programs\\Python\\Python312\\Lib\\site-packages\\django\\template\\base.py\", line 893, in _resolve_lookup\n    current = getattr(current, bit)\n              ^^^^^^^^^^^^^^^^^^^^^\nAttributeError: 'dict' object has no attribute 'symbol'\n\nDuring handling of the above exception, another exception occurred:\n\nTraceback (most recent call last):\n  File \"C:\\Users\\Eliana Galban\\AppData\\Local\\Programs\\Python\\Python312\\Lib\\site-packages\\django\\template\\base.py\", line 899, in _resolve_lookup\n    current = current[int(bit)]\n                      ^^^^^^^^\nValueError: invalid literal for int() with base 10: 'symbol'\n\nDuring handling of the above exception, another exception occurred:\n\nTraceback (most recent call last):\n  File \"C:\\Users\\Eliana Galban\\AppData\\Local\\Programs\\Python\\Python312\\Lib\\site-packages\\django\\template\\base.py\", line 906, in _resolve_lookup\n    raise VariableDoesNotExist(\ndjango.template.base.VariableDoesNotExist: Failed lookup for key [symbol] in {'data': {'id': '9b575b0d-a29b-4904-ae96-5085d5601387', 'client_order_id': '703c6569-2316-4230-8018-14309d55abfb', 'created_at': '2025-05-23T12:00:17.551456597Z', 'updated_at': '2025-05-23T12:00:17.552910807Z', 'submitted_at': '2025-05-23T12:00:17.551456597Z', 'filled_at': None, 'expired_at': None, 'canceled_at': None, 'failed_at': None, 'replaced_at': None, 'replaced_by': None, 'replaces': None, 'asset_id': '0e967a96-2a81-4eaf-91cc-83d5cce69717', 'symbol': 'MRVI', 'asset_class': 'us_equity', 'notional': None, 'qty': '1', 'filled_qty': '0', 'filled_avg_price': None, 'order_class': '', 'order_type': 'market', 'type': 'market', 'side': 'buy', 'position_intent': 'buy_to_open', 'time_in_force': 'gtc', 'limit_price': None, 'stop_price': None, 'status': 'pending_new', 'extended_hours': False, 'legs': None, 'trail_percent': None, 'trail_price': None, 'hwm': None, 'commission': '0', 'subtag': None, 'source': None, 'expires_at': '2025-08-21T20:00:00Z'}, 'order_id': '9b575b0d-a29b-4904-ae96-5085d5601387', 'status': 'pending_new'}"}
{"asctime": "2025-05-23 07:00:17,306", "levelname": "DEBUG", "name": "django.template", "module": "base", "funcName": "_resolve_lookup", "lineno": 933, "message": "Exception while resolving variable 'qty' in template 'trading/orden_resultado.html'.", "exc_info": "Traceback (most recent call last):\n  File \"C:\\Users\\Eliana Galban\\AppData\\Local\\Programs\\Python\\Python312\\Lib\\site-packages\\django\\template\\base.py\", line 883, in _resolve_lookup\n    current = current[bit]\n              ~~~~~~~^^^^^\nKeyError: 'qty'\n\nDuring handling of the above exception, another exception occurred:\n\nTraceback (most recent call last):\n  File \"C:\\Users\\Eliana Galban\\AppData\\Local\\Programs\\Python\\Python312\\Lib\\site-packages\\django\\template\\base.py\", line 893, in _resolve_lookup\n    current = getattr(current, bit)\n              ^^^^^^^^^^^^^^^^^^^^^\nAttributeError: 'dict' object has no attribute 'qty'\n\nDuring handling of the above exception, another exception occurred:\n\nTraceback (most recent call last):\n  File \"C:\\Users\\Eliana Galban\\AppData\\Local\\Programs\\Python\\Python312\\Lib\\site-packages\\django\\template\\base.py\", line 899, in _resolve_lookup\n    current = current[int(bit)]\n                      ^^^^^^^^\nValueError: invalid literal for int() with base 10: 'qty'\n\nDuring handling of the above exception, another exception occurred:\n\nTraceback (most recent call last):\n  File \"C:\\Users\\Eliana Galban\\AppData\\Local\\Programs\\Python\\Python312\\Lib\\site-packages\\django\\template\\base.py\", line 906, in _resolve_lookup\n    raise VariableDoesNotExist(\ndjango.template.base.VariableDoesNotExist: Failed lookup for key [qty] in {'data': {'id': '9b575b0d-a29b-4904-ae96-5085d5601387', 'client_order_id': '703c6569-2316-4230-8018-14309d55abfb', 'created_at': '2025-05-23T12:00:17.551456597Z', 'updated_at': '2025-05-23T12:00:17.552910807Z', 'submitted_at': '2025-05-23T12:00:17.551456597Z', 'filled_at': None, 'expired_at': None, 'canceled_at': None, 'failed_at': None, 'replaced_at': None, 'replaced_by': None, 'replaces': None, 'asset_id': '0e967a96-2a81-4eaf-91cc-83d5cce69717', 'symbol': 'MRVI', 'asset_class': 'us_equity', 'notional': None, 'qty': '1', 'filled_qty': '0', 'filled_avg_price': None, 'order_class': '', 'order_type': 'market', 'type': 'market', 'side': 'buy', 'position_intent': 'buy_to_open', 'time_in_force': 'gtc', 'limit_price': None, 'stop_price': None, 'status': 'pending_new', 'extended_hours': False, 'legs': None, 'trail_percent': None, 'trail_price': None, 'hwm': None, 'commission': '0', 'subtag': None, 'source': None, 'expires_at': '2025-08-21T20:00:00Z'}, 'order_id': '9b575b0d-a29b-4904-ae96-5085d5601387', 'status': 'pending_new'}"}
{"asctime": "2025-05-23 07:06:02,897", "levelname": "DEBUG", "name": "django.template", "module": "base", "funcName": "_resolve_lookup", "lineno": 933, "message": "Exception while resolving variable 'symbol' in template 'trading/orden_resultado.html'.", "exc_info": "Traceback (most recent call last):\n  File \"C:\\Users\\Eliana Galban\\AppData\\Local\\Programs\\Python\\Python312\\Lib\\site-packages\\django\\template\\base.py\", line 883, in _resolve_lookup\n    current = current[bit]\n              ~~~~~~~^^^^^\nKeyError: 'symbol'\n\nDuring handling of the above exception, another exception occurred:\n\nTraceback (most recent call last):\n  File \"C:\\Users\\Eliana Galban\\AppData\\Local\\Programs\\Python\\Python312\\Lib\\site-packages\\django\\template\\base.py\", line 893, in _resolve_lookup\n    current = getattr(current, bit)\n              ^^^^^^^^^^^^^^^^^^^^^\nAttributeError: 'dict' object has no attribute 'symbol'\n\nDuring handling of the above exception, another exception occurred:\n\nTraceback (most recent call last):\n  File \"C:\\Users\\Eliana Galban\\AppData\\Local\\Programs\\Python\\Python312\\Lib\\site-packages\\django\\template\\base.py\", line 899, in _resolve_lookup\n    current = current[int(bit)]\n                      ^^^^^^^^\nValueError: invalid literal for int() with base 10: 'symbol'\n\nDuring handling of the above exception, another exception occurred:\n\nTraceback (most recent call last):\n  File \"C:\\Users\\Eliana Galban\\AppData\\Local\\Programs\\Python\\Python312\\Lib\\site-packages\\django\\template\\base.py\", line 906, in _resolve_lookup\n    raise VariableDoesNotExist(\ndjango.template.base.VariableDoesNotExist: Failed lookup for key [symbol] in {'data': {'id': '7ad7a99d-712d-4bcf-9624-345489da769b', 'client_order_id': '5f5a7ade-8c06-4c6c-b12e-560c0ee1ca57', 'created_at': '2025-05-23T12:06:03.193749605Z', 'updated_at': '2025-05-23T12:06:03.195693925Z', 'submitted_at': '2025-05-23T12:06:03.193749605Z', 'filled_at': None, 'expired_at': None, 'canceled_at': None, 'failed_at': None, 'replaced_at': None, 'replaced_by': None, 'replaces': None, 'asset_id': '0e967a96-2a81-4eaf-91cc-83d5cce69717', 'symbol': 'MRVI', 'asset_class': 'us_equity', 'notional': None, 'qty': '1', 'filled_qty': '0', 'filled_avg_price': None, 'order_class': '', 'order_type': 'market', 'type': 'market', 'side': 'buy', 'position_intent': 'buy_to_open', 'time_in_force': 'gtc', 'limit_price': None, 'stop_price': None, 'status': 'pending_new', 'extended_hours': False, 'legs': None, 'trail_percent': None, 'trail_price': None, 'hwm': None, 'commission': '0', 'subtag': None, 'source': None, 'expires_at': '2025-08-21T20:00:00Z'}, 'order_id': '7ad7a99d-712d-4bcf-9624-345489da769b', 'status': 'pending_new'}"}
{"asctime": "2025-05-23 14:14:10,032", "levelname": "DEBUG", "name": "django.template", "module": "base", "funcName": "_resolve_lookup", "lineno": 941, "message": "Exception while resolving variable 'pago' in template 'accounts/perfil.html'.", "exc_info": "Traceback (most recent call last):\n  File \"C:\\Users\\Eliana Galban\\AccionesElBosque\\venv\\Lib\\site-packages\\django\\utils\\datastructures.py\", line 84, in __getitem__\n    list_ = super().__getitem__(key)\n            ^^^^^^^^^^^^^^^^^^^^^^^^\nKeyError: 'pago'\n\nDuring handling of the above exception, another exception occurred:\n\nTraceback (most recent call last):\n  File \"C:\\Users\\Eliana Galban\\AccionesElBosque\\venv\\Lib\\site-packages\\django\\template\\base.py\", line 891, in _resolve_lookup\n    current = current[bit]\n              ~~~~~~~^^^^^\n  File \"C:\\Users\\Eliana Galban\\AccionesElBosque\\venv\\Lib\\site-packages\\django\\utils\\datastructures.py\", line 86, in __getitem__\n    raise MultiValueDictKeyError(key)\ndjango.utils.datastructures.MultiValueDictKeyError: 'pago'\n\nDuring handling of the above exception, another exception occurred:\n\nTraceback (most recent call last):\n  File \"C:\\Users\\Eliana Galban\\AccionesElBosque\\venv\\Lib\\site-packages\\django\\template\\base.py\", line 901, in _resolve_lookup\n    current = getattr(current, bit)\n              ^^^^^^^^^^^^^^^^^^^^^\nAttributeError: 'QueryDict' object has no attribute 'pago'\n\nDuring handling of the above exception, another exception occurred:\n\nTraceback (most recent call last):\n  File \"C:\\Users\\Eliana Galban\\AccionesElBosque\\venv\\Lib\\site-packages\\django\\template\\base.py\", line 907, in _resolve_lookup\n    current = current[int(bit)]\n                      ^^^^^^^^\nValueError: invalid literal for int() with base 10: 'pago'\n\nDuring handling of the above exception, another exception occurred:\n\nTraceback (most recent call last):\n  File \"C:\\Users\\Eliana Galban\\AccionesElBosque\\venv\\Lib\\site-packages\\django\\template\\base.py\", line 914, in _resolve_lookup\n    raise VariableDoesNotExist(\ndjango.template.base.VariableDoesNotExist: Failed lookup for key [pago] in <QueryDict: {}>"}
{"asctime": "2025-05-23 14:14:10,087", "levelname": "DEBUG", "name": "django.template", "module": "base", "funcName": "_resolve_lookup", "lineno": 941, "message": "Exception while resolving variable 'pago' in template 'accounts/perfil.html'.", "exc_info": "Traceback (most recent call last):\n  File \"C:\\Users\\Eliana Galban\\AccionesElBosque\\venv\\Lib\\site-packages\\django\\utils\\datastructures.py\", line 84, in __getitem__\n    list_ = super().__getitem__(key)\n            ^^^^^^^^^^^^^^^^^^^^^^^^\nKeyError: 'pago'\n\nDuring handling of the above exception, another exception occurred:\n\nTraceback (most recent call last):\n  File \"C:\\Users\\Eliana Galban\\AccionesElBosque\\venv\\Lib\\site-packages\\django\\template\\base.py\", line 891, in _resolve_lookup\n    current = current[bit]\n              ~~~~~~~^^^^^\n  File \"C:\\Users\\Eliana Galban\\AccionesElBosque\\venv\\Lib\\site-packages\\django\\utils\\datastructures.py\", line 86, in __getitem__\n    raise MultiValueDictKeyError(key)\ndjango.utils.datastructures.MultiValueDictKeyError: 'pago'\n\nDuring handling of the above exception, another exception occurred:\n\nTraceback (most recent call last):\n  File \"C:\\Users\\Eliana Galban\\AccionesElBosque\\venv\\Lib\\site-packages\\django\\template\\base.py\", line 901, in _resolve_lookup\n    current = getattr(current, bit)\n              ^^^^^^^^^^^^^^^^^^^^^\nAttributeError: 'QueryDict' object has no attribute 'pago'\n\nDuring handling of the above exception, another exception occurred:\n\nTraceback (most recent call last):\n  File \"C:\\Users\\Eliana Galban\\AccionesElBosque\\venv\\Lib\\site-packages\\django\\template\\base.py\", line 907, in _resolve_lookup\n    current = current[int(bit)]\n                      ^^^^^^^^\nValueError: invalid literal for int() with base 10: 'pago'\n\nDuring handling of the above exception, another exception occurred:\n\nTraceback (most recent call last):\n  File \"C:\\Users\\Eliana Galban\\AccionesElBosque\\venv\\Lib\\site-packages\\django\\template\\base.py\", line 914, in _resolve_lookup\n    raise VariableDoesNotExist(\ndjango.template.base.VariableDoesNotExist: Failed lookup for key [pago] in <QueryDict: {}>"}
{"asctime": "2025-05-23 14:35:54,249", "levelname": "DEBUG", "name": "django.template", "module": "base", "funcName": "_resolve_lookup", "lineno": 941, "message": "Exception while resolving variable 'estados_pendientes' in template 'trading/orden_resultado.html'.", "exc_info": "Traceback (most recent call last):\n  File \"C:\\Users\\Eliana Galban\\AccionesElBosque\\venv\\Lib\\site-packages\\django\\template\\base.py\", line 891, in _resolve_lookup\n    current = current[bit]\n              ~~~~~~~^^^^^\n  File \"C:\\Users\\Eliana Galban\\AccionesElBosque\\venv\\Lib\\site-packages\\django\\template\\context.py\", line 88, in __getitem__\n    raise KeyError(key)\nKeyError: 'estados_pendientes'\n\nDuring handling of the above exception, another exception occurred:\n\nTraceback (most recent call last):\n  File \"C:\\Users\\Eliana Galban\\AccionesElBosque\\venv\\Lib\\site-packages\\django\\template\\base.py\", line 897, in _resolve_lookup\n    if isinstance(current, BaseContext) and getattr(\n                                            ^^^^^^^^\nAttributeError: type object 'RequestContext' has no attribute 'estados_pendientes'\n\nDuring handling of the above exception, another exception occurred:\n\nTraceback (most recent call last):\n  File \"C:\\Users\\Eliana Galban\\AccionesElBosque\\venv\\Lib\\site-packages\\django\\template\\base.py\", line 907, in _resolve_lookup\n    current = current[int(bit)]\n                      ^^^^^^^^\nValueError: invalid literal for int() with base 10: 'estados_pendientes'\n\nDuring handling of the above exception, another exception occurred:\n\nTraceback (most recent call last):\n  File \"C:\\Users\\Eliana Galban\\AccionesElBosque\\venv\\Lib\\site-packages\\django\\template\\base.py\", line 914, in _resolve_lookup\n    raise VariableDoesNotExist(\ndjango.template.base.VariableDoesNotExist: Failed lookup for key [estados_pendientes] in [{'True': True, 'False': False, 'None': None}, {'csrf_token': <SimpleLazyObject: <function csrf.<locals>._get_val at 0x000001B9AC940680>>, 'request': <WSGIRequest: POST '/trading/vender/'>, 'user': <SimpleLazyObject: <function AuthenticationMiddleware.process_request.<locals>.<lambda> at 0x000001B9AC9404A0>>, 'perms': PermWrapper(<SimpleLazyObject: <function AuthenticationMiddleware.process_request.<locals>.<lambda> at 0x000001B9AC9404A0>>), 'messages': <FallbackStorage: request=<WSGIRequest: POST '/trading/vender/'>>, 'DEFAULT_MESSAGE_LEVELS': {'DEBUG': 10, 'INFO': 20, 'SUCCESS': 25, 'WARNING': 30, 'ERROR': 40}}, {}, {'resultado': {'data': {'id': '350046c5-62cc-4248-b78f-6c0d5cfb7156', 'client_order_id': 'd6d49c19-190b-424a-90f7-d8274ca3f884', 'created_at': '2025-05-23T19:35:54.543554346Z', 'updated_at': '2025-05-23T19:35:54.544248686Z', 'submitted_at': '2025-05-23T19:35:54.543554346Z', 'filled_at': None, 'expired_at': None, 'canceled_at': None, 'failed_at': None, 'replaced_at': None, 'replaced_by': None, 'replaces': None, 'asset_id': '0e967a96-2a81-4eaf-91cc-83d5cce69717', 'symbol': 'MRVI', 'asset_class': 'us_equity', 'notional': None, 'qty': '2', 'filled_qty': '0', 'filled_avg_price': None, 'order_class': '', 'order_type': 'market', 'type': 'market', 'side': 'sell', 'position_intent': 'sell_to_close', 'time_in_force': 'gtc', 'limit_price': None, 'stop_price': None, 'status': 'pending_new', 'extended_hours': False, 'legs': None, 'trail_percent': None, 'trail_price': None, 'hwm': None, 'commission': '0', 'subtag': None, 'source': None, 'expires_at': '2025-08-21T20:00:00Z'}, 'order_id': '350046c5-62cc-4248-b78f-6c0d5cfb7156', 'status': 'pending_new'}}]"}
{"asctime": "2025-05-23 14:35:54,347", "levelname": "DEBUG", "name": "django.template", "module": "base", "funcName": "_resolve_lookup", "lineno": 941, "message": "Exception while resolving variable 'error' in template 'trading/orden_resultado.html'.", "exc_info": "Traceback (most recent call last):\n  File \"C:\\Users\\Eliana Galban\\AccionesElBosque\\venv\\Lib\\site-packages\\django\\template\\base.py\", line 891, in _resolve_lookup\n    current = current[bit]\n              ~~~~~~~^^^^^\nKeyError: 'error'\n\nDuring handling of the above exception, another exception occurred:\n\nTraceback (most recent call last):\n  File \"C:\\Users\\Eliana Galban\\AccionesElBosque\\venv\\Lib\\site-packages\\django\\template\\base.py\", line 901, in _resolve_lookup\n    current = getattr(current, bit)\n              ^^^^^^^^^^^^^^^^^^^^^\nAttributeError: 'dict' object has no attribute 'error'\n\nDuring handling of the above exception, another exception occurred:\n\nTraceback (most recent call last):\n  File \"C:\\Users\\Eliana Galban\\AccionesElBosque\\venv\\Lib\\site-packages\\django\\template\\base.py\", line 907, in _resolve_lookup\n    current = current[int(bit)]\n                      ^^^^^^^^\nValueError: invalid literal for int() with base 10: 'error'\n\nDuring handling of the above exception, another exception occurred:\n\nTraceback (most recent call last):\n  File \"C:\\Users\\Eliana Galban\\AccionesElBosque\\venv\\Lib\\site-packages\\django\\template\\base.py\", line 914, in _resolve_lookup\n    raise VariableDoesNotExist(\ndjango.template.base.VariableDoesNotExist: Failed lookup for key [error] in {'data': {'id': '350046c5-62cc-4248-b78f-6c0d5cfb7156', 'client_order_id': 'd6d49c19-190b-424a-90f7-d8274ca3f884', 'created_at': '2025-05-23T19:35:54.543554346Z', 'updated_at': '2025-05-23T19:35:54.544248686Z', 'submitted_at': '2025-05-23T19:35:54.543554346Z', 'filled_at': None, 'expired_at': None, 'canceled_at': None, 'failed_at': None, 'replaced_at': None, 'replaced_by': None, 'replaces': None, 'asset_id': '0e967a96-2a81-4eaf-91cc-83d5cce69717', 'symbol': 'MRVI', 'asset_class': 'us_equity', 'notional': None, 'qty': '2', 'filled_qty': '0', 'filled_avg_price': None, 'order_class': '', 'order_type': 'market', 'type': 'market', 'side': 'sell', 'position_intent': 'sell_to_close', 'time_in_force': 'gtc', 'limit_price': None, 'stop_price': None, 'status': 'pending_new', 'extended_hours': False, 'legs': None, 'trail_percent': None, 'trail_price': None, 'hwm': None, 'commission': '0', 'subtag': None, 'source': None, 'expires_at': '2025-08-21T20:00:00Z'}, 'order_id': '350046c5-62cc-4248-b78f-6c0d5cfb7156', 'status': 'pending_new'}"}
{"asctime": "2025-05-23 14:35:54,349", "levelname": "DEBUG", "name": "django.template", "module": "base", "funcName": "_resolve_lookup", "lineno": 941, "message": "Exception while resolving variable 'qty' in template 'trading/orden_resultado.html'.", "exc_info": "Traceback (most recent call last):\n  File \"C:\\Users\\Eliana Galban\\AccionesElBosque\\venv\\Lib\\site-packages\\django\\template\\base.py\", line 891, in _resolve_lookup\n    current = current[bit]\n              ~~~~~~~^^^^^\nKeyError: 'qty'\n\nDuring handling of the above exception, another exception occurred:\n\nTraceback (most recent call last):\n  File \"C:\\Users\\Eliana Galban\\AccionesElBosque\\venv\\Lib\\site-packages\\django\\template\\base.py\", line 901, in _resolve_lookup\n    current = getattr(current, bit)\n              ^^^^^^^^^^^^^^^^^^^^^\nAttributeError: 'dict' object has no attribute 'qty'\n\nDuring handling of the above exception, another exception occurred:\n\nTraceback (most recent call last):\n  File \"C:\\Users\\Eliana Galban\\AccionesElBosque\\venv\\Lib\\site-packages\\django\\template\\base.py\", line 907, in _resolve_lookup\n    current = current[int(bit)]\n                      ^^^^^^^^\nValueError: invalid literal for int() with base 10: 'qty'\n\nDuring handling of the above exception, another exception occurred:\n\nTraceback (most recent call last):\n  File \"C:\\Users\\Eliana Galban\\AccionesElBosque\\venv\\Lib\\site-packages\\django\\template\\base.py\", line 914, in _resolve_lookup\n    raise VariableDoesNotExist(\ndjango.template.base.VariableDoesNotExist: Failed lookup for key [qty] in {'data': {'id': '350046c5-62cc-4248-b78f-6c0d5cfb7156', 'client_order_id': 'd6d49c19-190b-424a-90f7-d8274ca3f884', 'created_at': '2025-05-23T19:35:54.543554346Z', 'updated_at': '2025-05-23T19:35:54.544248686Z', 'submitted_at': '2025-05-23T19:35:54.543554346Z', 'filled_at': None, 'expired_at': None, 'canceled_at': None, 'failed_at': None, 'replaced_at': None, 'replaced_by': None, 'replaces': None, 'asset_id': '0e967a96-2a81-4eaf-91cc-83d5cce69717', 'symbol': 'MRVI', 'asset_class': 'us_equity', 'notional': None, 'qty': '2', 'filled_qty': '0', 'filled_avg_price': None, 'order_class': '', 'order_type': 'market', 'type': 'market', 'side': 'sell', 'position_intent': 'sell_to_close', 'time_in_force': 'gtc', 'limit_price': None, 'stop_price': None, 'status': 'pending_new', 'extended_hours': False, 'legs': None, 'trail_percent': None, 'trail_price': None, 'hwm': None, 'commission': '0', 'subtag': None, 'source': None, 'expires_at': '2025-08-21T20:00:00Z'}, 'order_id': '350046c5-62cc-4248-b78f-6c0d5cfb7156', 'status': 'pending_new'}"}
{"asctime": "2025-05-23 14:58:45,915", "levelname": "DEBUG", "name": "django.template", "module": "base", "funcName": "_resolve_lookup", "lineno": 941, "message": "Exception while resolving variable 'data' in template 'trading/orden_resultado.html'.", "exc_info": "Traceback (most recent call last):\n  File \"C:\\Users\\Eliana Galban\\AccionesElBosque\\venv\\Lib\\site-packages\\django\\template\\base.py\", line 891, in _resolve_lookup\n    current = current[bit]\n              ~~~~~~~^^^^^\nTypeError: string indices must be integers, not 'str'\n\nDuring handling of the above exception, another exception occurred:\n\nTraceback (most recent call last):\n  File \"C:\\Users\\Eliana Galban\\AccionesElBosque\\venv\\Lib\\site-packages\\django\\template\\base.py\", line 901, in _resolve_lookup\n    current = getattr(current, bit)\n              ^^^^^^^^^^^^^^^^^^^^^\nAttributeError: 'str' object has no attribute 'data'\n\nDuring handling of the above exception, another exception occurred:\n\nTraceback (most recent call last):\n  File \"C:\\Users\\Eliana Galban\\AccionesElBosque\\venv\\Lib\\site-packages\\django\\template\\base.py\", line 907, in _resolve_lookup\n    current = current[int(bit)]\n                      ^^^^^^^^\nValueError: invalid literal for int() with base 10: 'data'\n\nDuring handling of the above exception, another exception occurred:\n\nTraceback (most recent call last):\n  File \"C:\\Users\\Eliana Galban\\AccionesElBosque\\venv\\Lib\\site-packages\\django\\template\\base.py\", line 914, in _resolve_lookup\n    raise VariableDoesNotExist(\ndjango.template.base.VariableDoesNotExist: Failed lookup for key [data] in 'Orden de venta completada. Nuevo saldo: 2002.1854'"}
{"asctime": "2025-05-23 14:58:45,947", "levelname": "DEBUG", "name": "django.template", "module": "base", "funcName": "_resolve_lookup", "lineno": 941, "message": "Exception while resolving variable 'data' in template 'trading/orden_resultado.html'.", "exc_info": "Traceback (most recent call last):\n  File \"C:\\Users\\Eliana Galban\\AccionesElBosque\\venv\\Lib\\site-packages\\django\\template\\base.py\", line 891, in _resolve_lookup\n    current = current[bit]\n              ~~~~~~~^^^^^\nTypeError: string indices must be integers, not 'str'\n\nDuring handling of the above exception, another exception occurred:\n\nTraceback (most recent call last):\n  File \"C:\\Users\\Eliana Galban\\AccionesElBosque\\venv\\Lib\\site-packages\\django\\template\\base.py\", line 901, in _resolve_lookup\n    current = getattr(current, bit)\n              ^^^^^^^^^^^^^^^^^^^^^\nAttributeError: 'str' object has no attribute 'data'\n\nDuring handling of the above exception, another exception occurred:\n\nTraceback (most recent call last):\n  File \"C:\\Users\\Eliana Galban\\AccionesElBosque\\venv\\Lib\\site-packages\\django\\template\\base.py\", line 907, in _resolve_lookup\n    current = current[int(bit)]\n                      ^^^^^^^^\nValueError: invalid literal for int() with base 10: 'data'\n\nDuring handling of the above exception, another exception occurred:\n\nTraceback (most recent call last):\n  File \"C:\\Users\\Eliana Galban\\AccionesElBosque\\venv\\Lib\\site-packages\\django\\template\\base.py\", line 914, in _resolve_lookup\n    raise VariableDoesNotExist(\ndjango.template.base.VariableDoesNotExist: Failed lookup for key [data] in 'Orden de venta completada. Nuevo saldo: 2002.1854'"}
{"asctime": "2025-05-23 14:58:45,951", "levelname": "DEBUG", "name": "django.template", "module": "base", "funcName": "_resolve_lookup", "lineno": 941, "message": "Exception while resolving variable 'estados_pendientes' in template 'trading/orden_resultado.html'.", "exc_info": "Traceback (most recent call last):\n  File \"C:\\Users\\Eliana Galban\\AccionesElBosque\\venv\\Lib\\site-packages\\django\\template\\base.py\", line 891, in _resolve_lookup\n    current = current[bit]\n              ~~~~~~~^^^^^\n  File \"C:\\Users\\Eliana Galban\\AccionesElBosque\\venv\\Lib\\site-packages\\django\\template\\context.py\", line 88, in __getitem__\n    raise KeyError(key)\nKeyError: 'estados_pendientes'\n\nDuring handling of the above exception, another exception occurred:\n\nTraceback (most recent call last):\n  File \"C:\\Users\\Eliana Galban\\AccionesElBosque\\venv\\Lib\\site-packages\\django\\template\\base.py\", line 897, in _resolve_lookup\n    if isinstance(current, BaseContext) and getattr(\n                                            ^^^^^^^^\nAttributeError: type object 'RequestContext' has no attribute 'estados_pendientes'\n\nDuring handling of the above exception, another exception occurred:\n\nTraceback (most recent call last):\n  File \"C:\\Users\\Eliana Galban\\AccionesElBosque\\venv\\Lib\\site-packages\\django\\template\\base.py\", line 907, in _resolve_lookup\n    current = current[int(bit)]\n                      ^^^^^^^^\nValueError: invalid literal for int() with base 10: 'estados_pendientes'\n\nDuring handling of the above exception, another exception occurred:\n\nTraceback (most recent call last):\n  File \"C:\\Users\\Eliana Galban\\AccionesElBosque\\venv\\Lib\\site-packages\\django\\template\\base.py\", line 914, in _resolve_lookup\n    raise VariableDoesNotExist(\ndjango.template.base.VariableDoesNotExist: Failed lookup for key [estados_pendientes] in [{'True': True, 'False': False, 'None': None}, {'csrf_token': <SimpleLazyObject: <function csrf.<locals>._get_val at 0x0000025FD6894E00>>, 'request': <WSGIRequest: POST '/trading/vender/'>, 'user': <SimpleLazyObject: <function AuthenticationMiddleware.process_request.<locals>.<lambda> at 0x0000025FD6894400>>, 'perms': PermWrapper(<SimpleLazyObject: <function AuthenticationMiddleware.process_request.<locals>.<lambda> at 0x0000025FD6894400>>), 'messages': <FallbackStorage: request=<WSGIRequest: POST '/trading/vender/'>>, 'DEFAULT_MESSAGE_LEVELS': {'DEBUG': 10, 'INFO': 20, 'SUCCESS': 25, 'WARNING': 30, 'ERROR': 40}}, {}, {'resultado': 'Orden de venta completada. Nuevo saldo: 2002.1854'}]"}
{"asctime": "2025-05-23 14:58:45,965", "levelname": "DEBUG", "name": "django.template", "module": "base", "funcName": "_resolve_lookup", "lineno": 941, "message": "Exception while resolving variable 'error' in template 'trading/orden_resultado.html'.", "exc_info": "Traceback (most recent call last):\n  File \"C:\\Users\\Eliana Galban\\AccionesElBosque\\venv\\Lib\\site-packages\\django\\template\\base.py\", line 891, in _resolve_lookup\n    current = current[bit]\n              ~~~~~~~^^^^^\nTypeError: string indices must be integers, not 'str'\n\nDuring handling of the above exception, another exception occurred:\n\nTraceback (most recent call last):\n  File \"C:\\Users\\Eliana Galban\\AccionesElBosque\\venv\\Lib\\site-packages\\django\\template\\base.py\", line 901, in _resolve_lookup\n    current = getattr(current, bit)\n              ^^^^^^^^^^^^^^^^^^^^^\nAttributeError: 'str' object has no attribute 'error'\n\nDuring handling of the above exception, another exception occurred:\n\nTraceback (most recent call last):\n  File \"C:\\Users\\Eliana Galban\\AccionesElBosque\\venv\\Lib\\site-packages\\django\\template\\base.py\", line 907, in _resolve_lookup\n    current = current[int(bit)]\n                      ^^^^^^^^\nValueError: invalid literal for int() with base 10: 'error'\n\nDuring handling of the above exception, another exception occurred:\n\nTraceback (most recent call last):\n  File \"C:\\Users\\Eliana Galban\\AccionesElBosque\\venv\\Lib\\site-packages\\django\\template\\base.py\", line 914, in _resolve_lookup\n    raise VariableDoesNotExist(\ndjango.template.base.VariableDoesNotExist: Failed lookup for key [error] in 'Orden de venta completada. Nuevo saldo: 2002.1854'"}
{"asctime": "2025-05-23 14:58:45,968", "levelname": "DEBUG", "name": "django.template", "module": "base", "funcName": "_resolve_lookup", "lineno": 941, "message": "Exception while resolving variable 'data' in template 'trading/orden_resultado.html'.", "exc_info": "Traceback (most recent call last):\n  File \"C:\\Users\\Eliana Galban\\AccionesElBosque\\venv\\Lib\\site-packages\\django\\template\\base.py\", line 891, in _resolve_lookup\n    current = current[bit]\n              ~~~~~~~^^^^^\nTypeError: string indices must be integers, not 'str'\n\nDuring handling of the above exception, another exception occurred:\n\nTraceback (most recent call last):\n  File \"C:\\Users\\Eliana Galban\\AccionesElBosque\\venv\\Lib\\site-packages\\django\\template\\base.py\", line 901, in _resolve_lookup\n    current = getattr(current, bit)\n              ^^^^^^^^^^^^^^^^^^^^^\nAttributeError: 'str' object has no attribute 'data'\n\nDuring handling of the above exception, another exception occurred:\n\nTraceback (most recent call last):\n  File \"C:\\Users\\Eliana Galban\\AccionesElBosque\\venv\\Lib\\site-packages\\django\\template\\base.py\", line 907, in _resolve_lookup\n    current = current[int(bit)]\n                      ^^^^^^^^\nValueError: invalid literal for int() with base 10: 'data'\n\nDuring handling of the above exception, another exception occurred:\n\nTraceback (most recent call last):\n  File \"C:\\Users\\Eliana Galban\\AccionesElBosque\\venv\\Lib\\site-packages\\django\\template\\base.py\", line 914, in _resolve_lookup\n    raise VariableDoesNotExist(\ndjango.template.base.VariableDoesNotExist: Failed lookup for key [data] in 'Orden de venta completada. Nuevo saldo: 2002.1854'"}
{"asctime": "2025-05-23 15:07:27,135", "levelname": "DEBUG", "name": "django.template", "module": "base", "funcName": "_resolve_lookup", "lineno": 941, "message": "Exception while resolving variable 'data' in template 'trading/orden_resultado.html'.", "exc_info": "Traceback (most recent call last):\n  File \"C:\\Users\\Eliana Galban\\AccionesElBosque\\venv\\Lib\\site-packages\\django\\template\\base.py\", line 891, in _resolve_lookup\n    current = current[bit]\n              ~~~~~~~^^^^^\nKeyError: 'data'\n\nDuring handling of the above exception, another exception occurred:\n\nTraceback (most recent call last):\n  File \"C:\\Users\\Eliana Galban\\AccionesElBosque\\venv\\Lib\\site-packages\\django\\template\\base.py\", line 901, in _resolve_lookup\n    current = getattr(current, bit)\n              ^^^^^^^^^^^^^^^^^^^^^\nAttributeError: 'dict' object has no attribute 'data'\n\nDuring handling of the above exception, another exception occurred:\n\nTraceback (most recent call last):\n  File \"C:\\Users\\Eliana Galban\\AccionesElBosque\\venv\\Lib\\site-packages\\django\\template\\base.py\", line 907, in _resolve_lookup\n    current = current[int(bit)]\n                      ^^^^^^^^\nValueError: invalid literal for int() with base 10: 'data'\n\nDuring handling of the above exception, another exception occurred:\n\nTraceback (most recent call last):\n  File \"C:\\Users\\Eliana Galban\\AccionesElBosque\\venv\\Lib\\site-packages\\django\\template\\base.py\", line 914, in _resolve_lookup\n    raise VariableDoesNotExist(\ndjango.template.base.VariableDoesNotExist: Failed lookup for key [data] in {'status': 'accepted', 'order_id': '847c9727-e454-4c8e-9339-e2def823b8f3', 'symbol': 'MRVI', 'qty': 3}"}
{"asctime": "2025-05-23 15:07:27,137", "levelname": "DEBUG", "name": "django.template", "module": "base", "funcName": "_resolve_lookup", "lineno": 941, "message": "Exception while resolving variable 'qty' in template 'trading/orden_resultado.html'.", "exc_info": "Traceback (most recent call last):\n  File \"C:\\Users\\Eliana Galban\\AccionesElBosque\\venv\\Lib\\site-packages\\django\\template\\base.py\", line 891, in _resolve_lookup\n    current = current[bit]\n              ~~~~~~~^^^^^\n  File \"C:\\Users\\Eliana Galban\\AccionesElBosque\\venv\\Lib\\site-packages\\django\\template\\context.py\", line 88, in __getitem__\n    raise KeyError(key)\nKeyError: 'qty'\n\nDuring handling of the above exception, another exception occurred:\n\nTraceback (most recent call last):\n  File \"C:\\Users\\Eliana Galban\\AccionesElBosque\\venv\\Lib\\site-packages\\django\\template\\base.py\", line 897, in _resolve_lookup\n    if isinstance(current, BaseContext) and getattr(\n                                            ^^^^^^^^\nAttributeError: type object 'RequestContext' has no attribute 'qty'\n\nDuring handling of the above exception, another exception occurred:\n\nTraceback (most recent call last):\n  File \"C:\\Users\\Eliana Galban\\AccionesElBosque\\venv\\Lib\\site-packages\\django\\template\\base.py\", line 907, in _resolve_lookup\n    current = current[int(bit)]\n                      ^^^^^^^^\nValueError: invalid literal for int() with base 10: 'qty'\n\nDuring handling of the above exception, another exception occurred:\n\nTraceback (most recent call last):\n  File \"C:\\Users\\Eliana Galban\\AccionesElBosque\\venv\\Lib\\site-packages\\django\\template\\base.py\", line 914, in _resolve_lookup\n    raise VariableDoesNotExist(\ndjango.template.base.VariableDoesNotExist: Failed lookup for key [qty] in [{'True': True, 'False': False, 'None': None}, {'csrf_token': <SimpleLazyObject: <function csrf.<locals>._get_val at 0x000001B530606700>>, 'request': <WSGIRequest: POST '/trading/vender/'>, 'user': <SimpleLazyObject: <function AuthenticationMiddleware.process_request.<locals>.<lambda> at 0x000001B53BE8B060>>, 'perms': PermWrapper(<SimpleLazyObject: <function AuthenticationMiddleware.process_request.<locals>.<lambda> at 0x000001B53BE8B060>>), 'messages': <FallbackStorage: request=<WSGIRequest: POST '/trading/vender/'>>, 'DEFAULT_MESSAGE_LEVELS': {'DEBUG': 10, 'INFO': 20, 'SUCCESS': 25, 'WARNING': 30, 'ERROR': 40}}, {}, {'resultado': {'status': 'accepted', 'order_id': '847c9727-e454-4c8e-9339-e2def823b8f3', 'symbol': 'MRVI', 'qty': 3}, 'estados_pendientes': ['pending', 'new', 'accepted', 'pending_new']}]"}
{"asctime": "2025-05-23 15:07:27,138", "levelname": "DEBUG", "name": "django.template", "module": "base", "funcName": "_resolve_lookup", "lineno": 941, "message": "Exception while resolving variable 'data' in template 'trading/orden_resultado.html'.", "exc_info": "Traceback (most recent call last):\n  File \"C:\\Users\\Eliana Galban\\AccionesElBosque\\venv\\Lib\\site-packages\\django\\template\\base.py\", line 891, in _resolve_lookup\n    current = current[bit]\n              ~~~~~~~^^^^^\nKeyError: 'data'\n\nDuring handling of the above exception, another exception occurred:\n\nTraceback (most recent call last):\n  File \"C:\\Users\\Eliana Galban\\AccionesElBosque\\venv\\Lib\\site-packages\\django\\template\\base.py\", line 901, in _resolve_lookup\n    current = getattr(current, bit)\n              ^^^^^^^^^^^^^^^^^^^^^\nAttributeError: 'dict' object has no attribute 'data'\n\nDuring handling of the above exception, another exception occurred:\n\nTraceback (most recent call last):\n  File \"C:\\Users\\Eliana Galban\\AccionesElBosque\\venv\\Lib\\site-packages\\django\\template\\base.py\", line 907, in _resolve_lookup\n    current = current[int(bit)]\n                      ^^^^^^^^\nValueError: invalid literal for int() with base 10: 'data'\n\nDuring handling of the above exception, another exception occurred:\n\nTraceback (most recent call last):\n  File \"C:\\Users\\Eliana Galban\\AccionesElBosque\\venv\\Lib\\site-packages\\django\\template\\base.py\", line 914, in _resolve_lookup\n    raise VariableDoesNotExist(\ndjango.template.base.VariableDoesNotExist: Failed lookup for key [data] in {'status': 'accepted', 'order_id': '847c9727-e454-4c8e-9339-e2def823b8f3', 'symbol': 'MRVI', 'qty': 3}"}
{"asctime": "2025-05-23 15:20:53,235", "levelname": "DEBUG", "name": "django.template", "module": "base", "funcName": "_resolve_lookup", "lineno": 941, "message": "Exception while resolving variable 'pago' in template 'accounts/perfil.html'.", "exc_info": "Traceback (most recent call last):\n  File \"C:\\Users\\Eliana Galban\\AccionesElBosque\\venv\\Lib\\site-packages\\django\\utils\\datastructures.py\", line 84, in __getitem__\n    list_ = super().__getitem__(key)\n            ^^^^^^^^^^^^^^^^^^^^^^^^\nKeyError: 'pago'\n\nDuring handling of the above exception, another exception occurred:\n\nTraceback (most recent call last):\n  File \"C:\\Users\\Eliana Galban\\AccionesElBosque\\venv\\Lib\\site-packages\\django\\template\\base.py\", line 891, in _resolve_lookup\n    current = current[bit]\n              ~~~~~~~^^^^^\n  File \"C:\\Users\\Eliana Galban\\AccionesElBosque\\venv\\Lib\\site-packages\\django\\utils\\datastructures.py\", line 86, in __getitem__\n    raise MultiValueDictKeyError(key)\ndjango.utils.datastructures.MultiValueDictKeyError: 'pago'\n\nDuring handling of the above exception, another exception occurred:\n\nTraceback (most recent call last):\n  File \"C:\\Users\\Eliana Galban\\AccionesElBosque\\venv\\Lib\\site-packages\\django\\template\\base.py\", line 901, in _resolve_lookup\n    current = getattr(current, bit)\n              ^^^^^^^^^^^^^^^^^^^^^\nAttributeError: 'QueryDict' object has no attribute 'pago'\n\nDuring handling of the above exception, another exception occurred:\n\nTraceback (most recent call last):\n  File \"C:\\Users\\Eliana Galban\\AccionesElBosque\\venv\\Lib\\site-packages\\django\\template\\base.py\", line 907, in _resolve_lookup\n    current = current[int(bit)]\n                      ^^^^^^^^\nValueError: invalid literal for int() with base 10: 'pago'\n\nDuring handling of the above exception, another exception occurred:\n\nTraceback (most recent call last):\n  File \"C:\\Users\\Eliana Galban\\AccionesElBosque\\venv\\Lib\\site-packages\\django\\template\\base.py\", line 914, in _resolve_lookup\n    raise VariableDoesNotExist(\ndjango.template.base.VariableDoesNotExist: Failed lookup for key [pago] in <QueryDict: {}>"}
{"asctime": "2025-05-23 15:20:53,299", "levelname": "DEBUG", "name": "django.template", "module": "base", "funcName": "_resolve_lookup", "lineno": 941, "message": "Exception while resolving variable 'pago' in template 'accounts/perfil.html'.", "exc_info": "Traceback (most recent call last):\n  File \"C:\\Users\\Eliana Galban\\AccionesElBosque\\venv\\Lib\\site-packages\\django\\utils\\datastructures.py\", line 84, in __getitem__\n    list_ = super().__getitem__(key)\n            ^^^^^^^^^^^^^^^^^^^^^^^^\nKeyError: 'pago'\n\nDuring handling of the above exception, another exception occurred:\n\nTraceback (most recent call last):\n  File \"C:\\Users\\Eliana Galban\\AccionesElBosque\\venv\\Lib\\site-packages\\django\\template\\base.py\", line 891, in _resolve_lookup\n    current = current[bit]\n              ~~~~~~~^^^^^\n  File \"C:\\Users\\Eliana Galban\\AccionesElBosque\\venv\\Lib\\site-packages\\django\\utils\\datastructures.py\", line 86, in __getitem__\n    raise MultiValueDictKeyError(key)\ndjango.utils.datastructures.MultiValueDictKeyError: 'pago'\n\nDuring handling of the above exception, another exception occurred:\n\nTraceback (most recent call last):\n  File \"C:\\Users\\Eliana Galban\\AccionesElBosque\\venv\\Lib\\site-packages\\django\\template\\base.py\", line 901, in _resolve_lookup\n    current = getattr(current, bit)\n              ^^^^^^^^^^^^^^^^^^^^^\nAttributeError: 'QueryDict' object has no attribute 'pago'\n\nDuring handling of the above exception, another exception occurred:\n\nTraceback (most recent call last):\n  File \"C:\\Users\\Eliana Galban\\AccionesElBosque\\venv\\Lib\\site-packages\\django\\template\\base.py\", line 907, in _resolve_lookup\n    current = current[int(bit)]\n                      ^^^^^^^^\nValueError: invalid literal for int() with base 10: 'pago'\n\nDuring handling of the above exception, another exception occurred:\n\nTraceback (most recent call last):\n  File \"C:\\Users\\Eliana Galban\\AccionesElBosque\\venv\\Lib\\site-packages\\django\\template\\base.py\", line 914, in _resolve_lookup\n    raise VariableDoesNotExist(\ndjango.template.base.VariableDoesNotExist: Failed lookup for key [pago] in <QueryDict: {}>"}
{"asctime": "2025-05-23 16:48:56,463", "levelname": "DEBUG", "name": "django.template", "module": "base", "funcName": "_resolve_lookup", "lineno": 941, "message": "Exception while resolving variable 'pago' in template 'accounts/perfil.html'.", "exc_info": "Traceback (most recent call last):\n  File \"C:\\Users\\Eliana Galban\\AccionesElBosque\\venv\\Lib\\site-packages\\django\\utils\\datastructures.py\", line 84, in __getitem__\n    list_ = super().__getitem__(key)\n            ^^^^^^^^^^^^^^^^^^^^^^^^\nKeyError: 'pago'\n\nDuring handling of the above exception, another exception occurred:\n\nTraceback (most recent call last):\n  File \"C:\\Users\\Eliana Galban\\AccionesElBosque\\venv\\Lib\\site-packages\\django\\template\\base.py\", line 891, in _resolve_lookup\n    current = current[bit]\n              ~~~~~~~^^^^^\n  File \"C:\\Users\\Eliana Galban\\AccionesElBosque\\venv\\Lib\\site-packages\\django\\utils\\datastructures.py\", line 86, in __getitem__\n    raise MultiValueDictKeyError(key)\ndjango.utils.datastructures.MultiValueDictKeyError: 'pago'\n\nDuring handling of the above exception, another exception occurred:\n\nTraceback (most recent call last):\n  File \"C:\\Users\\Eliana Galban\\AccionesElBosque\\venv\\Lib\\site-packages\\django\\template\\base.py\", line 901, in _resolve_lookup\n    current = getattr(current, bit)\n              ^^^^^^^^^^^^^^^^^^^^^\nAttributeError: 'QueryDict' object has no attribute 'pago'\n\nDuring handling of the above exception, another exception occurred:\n\nTraceback (most recent call last):\n  File \"C:\\Users\\Eliana Galban\\AccionesElBosque\\venv\\Lib\\site-packages\\django\\template\\base.py\", line 907, in _resolve_lookup\n    current = current[int(bit)]\n                      ^^^^^^^^\nValueError: invalid literal for int() with base 10: 'pago'\n\nDuring handling of the above exception, another exception occurred:\n\nTraceback (most recent call last):\n  File \"C:\\Users\\Eliana Galban\\AccionesElBosque\\venv\\Lib\\site-packages\\django\\template\\base.py\", line 914, in _resolve_lookup\n    raise VariableDoesNotExist(\ndjango.template.base.VariableDoesNotExist: Failed lookup for key [pago] in <QueryDict: {}>"}
{"asctime": "2025-05-23 16:48:56,508", "levelname": "DEBUG", "name": "django.template", "module": "base", "funcName": "_resolve_lookup", "lineno": 941, "message": "Exception while resolving variable 'pago' in template 'accounts/perfil.html'.", "exc_info": "Traceback (most recent call last):\n  File \"C:\\Users\\Eliana Galban\\AccionesElBosque\\venv\\Lib\\site-packages\\django\\utils\\datastructures.py\", line 84, in __getitem__\n    list_ = super().__getitem__(key)\n            ^^^^^^^^^^^^^^^^^^^^^^^^\nKeyError: 'pago'\n\nDuring handling of the above exception, another exception occurred:\n\nTraceback (most recent call last):\n  File \"C:\\Users\\Eliana Galban\\AccionesElBosque\\venv\\Lib\\site-packages\\django\\template\\base.py\", line 891, in _resolve_lookup\n    current = current[bit]\n              ~~~~~~~^^^^^\n  File \"C:\\Users\\Eliana Galban\\AccionesElBosque\\venv\\Lib\\site-packages\\django\\utils\\datastructures.py\", line 86, in __getitem__\n    raise MultiValueDictKeyError(key)\ndjango.utils.datastructures.MultiValueDictKeyError: 'pago'\n\nDuring handling of the above exception, another exception occurred:\n\nTraceback (most recent call last):\n  File \"C:\\Users\\Eliana Galban\\AccionesElBosque\\venv\\Lib\\site-packages\\django\\template\\base.py\", line 901, in _resolve_lookup\n    current = getattr(current, bit)\n              ^^^^^^^^^^^^^^^^^^^^^\nAttributeError: 'QueryDict' object has no attribute 'pago'\n\nDuring handling of the above exception, another exception occurred:\n\nTraceback (most recent call last):\n  File \"C:\\Users\\Eliana Galban\\AccionesElBosque\\venv\\Lib\\site-packages\\django\\template\\base.py\", line 907, in _resolve_lookup\n    current = current[int(bit)]\n                      ^^^^^^^^\nValueError: invalid literal for int() with base 10: 'pago'\n\nDuring handling of the above exception, another exception occurred:\n\nTraceback (most recent call last):\n  File \"C:\\Users\\Eliana Galban\\AccionesElBosque\\venv\\Lib\\site-packages\\django\\template\\base.py\", line 914, in _resolve_lookup\n    raise VariableDoesNotExist(\ndjango.template.base.VariableDoesNotExist: Failed lookup for key [pago] in <QueryDict: {}>"}
{"asctime": "2025-05-23 16:51:35,960", "levelname": "DEBUG", "name": "django.template", "module": "base", "funcName": "_resolve_lookup", "lineno": 941, "message": "Exception while resolving variable 'pago' in template 'accounts/perfil.html'.", "exc_info": "Traceback (most recent call last):\n  File \"C:\\Users\\Eliana Galban\\AccionesElBosque\\venv\\Lib\\site-packages\\django\\utils\\datastructures.py\", line 84, in __getitem__\n    list_ = super().__getitem__(key)\n            ^^^^^^^^^^^^^^^^^^^^^^^^\nKeyError: 'pago'\n\nDuring handling of the above exception, another exception occurred:\n\nTraceback (most recent call last):\n  File \"C:\\Users\\Eliana Galban\\AccionesElBosque\\venv\\Lib\\site-packages\\django\\template\\base.py\", line 891, in _resolve_lookup\n    current = current[bit]\n              ~~~~~~~^^^^^\n  File \"C:\\Users\\Eliana Galban\\AccionesElBosque\\venv\\Lib\\site-packages\\django\\utils\\datastructures.py\", line 86, in __getitem__\n    raise MultiValueDictKeyError(key)\ndjango.utils.datastructures.MultiValueDictKeyError: 'pago'\n\nDuring handling of the above exception, another exception occurred:\n\nTraceback (most recent call last):\n  File \"C:\\Users\\Eliana Galban\\AccionesElBosque\\venv\\Lib\\site-packages\\django\\template\\base.py\", line 901, in _resolve_lookup\n    current = getattr(current, bit)\n              ^^^^^^^^^^^^^^^^^^^^^\nAttributeError: 'QueryDict' object has no attribute 'pago'\n\nDuring handling of the above exception, another exception occurred:\n\nTraceback (most recent call last):\n  File \"C:\\Users\\Eliana Galban\\AccionesElBosque\\venv\\Lib\\site-packages\\django\\template\\base.py\", line 907, in _resolve_lookup\n    current = current[int(bit)]\n                      ^^^^^^^^\nValueError: invalid literal for int() with base 10: 'pago'\n\nDuring handling of the above exception, another exception occurred:\n\nTraceback (most recent call last):\n  File \"C:\\Users\\Eliana Galban\\AccionesElBosque\\venv\\Lib\\site-packages\\django\\template\\base.py\", line 914, in _resolve_lookup\n    raise VariableDoesNotExist(\ndjango.template.base.VariableDoesNotExist: Failed lookup for key [pago] in <QueryDict: {}>"}
{"asctime": "2025-05-23 16:51:35,966", "levelname": "DEBUG", "name": "django.template", "module": "base", "funcName": "_resolve_lookup", "lineno": 941, "message": "Exception while resolving variable 'pago' in template 'accounts/perfil.html'.", "exc_info": "Traceback (most recent call last):\n  File \"C:\\Users\\Eliana Galban\\AccionesElBosque\\venv\\Lib\\site-packages\\django\\utils\\datastructures.py\", line 84, in __getitem__\n    list_ = super().__getitem__(key)\n            ^^^^^^^^^^^^^^^^^^^^^^^^\nKeyError: 'pago'\n\nDuring handling of the above exception, another exception occurred:\n\nTraceback (most recent call last):\n  File \"C:\\Users\\Eliana Galban\\AccionesElBosque\\venv\\Lib\\site-packages\\django\\template\\base.py\", line 891, in _resolve_lookup\n    current = current[bit]\n              ~~~~~~~^^^^^\n  File \"C:\\Users\\Eliana Galban\\AccionesElBosque\\venv\\Lib\\site-packages\\django\\utils\\datastructures.py\", line 86, in __getitem__\n    raise MultiValueDictKeyError(key)\ndjango.utils.datastructures.MultiValueDictKeyError: 'pago'\n\nDuring handling of the above exception, another exception occurred:\n\nTraceback (most recent call last):\n  File \"C:\\Users\\Eliana Galban\\AccionesElBosque\\venv\\Lib\\site-packages\\django\\template\\base.py\", line 901, in _resolve_lookup\n    current = getattr(current, bit)\n              ^^^^^^^^^^^^^^^^^^^^^\nAttributeError: 'QueryDict' object has no attribute 'pago'\n\nDuring handling of the above exception, another exception occurred:\n\nTraceback (most recent call last):\n  File \"C:\\Users\\Eliana Galban\\AccionesElBosque\\venv\\Lib\\site-packages\\django\\template\\base.py\", line 907, in _resolve_lookup\n    current = current[int(bit)]\n                      ^^^^^^^^\nValueError: invalid literal for int() with base 10: 'pago'\n\nDuring handling of the above exception, another exception occurred:\n\nTraceback (most recent call last):\n  File \"C:\\Users\\Eliana Galban\\AccionesElBosque\\venv\\Lib\\site-packages\\django\\template\\base.py\", line 914, in _resolve_lookup\n    raise VariableDoesNotExist(\ndjango.template.base.VariableDoesNotExist: Failed lookup for key [pago] in <QueryDict: {}>"}
{"asctime": "2025-05-23 16:57:14,980", "levelname": "DEBUG", "name": "django.template", "module": "base", "funcName": "_resolve_lookup", "lineno": 941, "message": "Exception while resolving variable 'pago' in template 'accounts/perfil.html'.", "exc_info": "Traceback (most recent call last):\n  File \"C:\\Users\\Eliana Galban\\AccionesElBosque\\venv\\Lib\\site-packages\\django\\utils\\datastructures.py\", line 84, in __getitem__\n    list_ = super().__getitem__(key)\n            ^^^^^^^^^^^^^^^^^^^^^^^^\nKeyError: 'pago'\n\nDuring handling of the above exception, another exception occurred:\n\nTraceback (most recent call last):\n  File \"C:\\Users\\Eliana Galban\\AccionesElBosque\\venv\\Lib\\site-packages\\django\\template\\base.py\", line 891, in _resolve_lookup\n    current = current[bit]\n              ~~~~~~~^^^^^\n  File \"C:\\Users\\Eliana Galban\\AccionesElBosque\\venv\\Lib\\site-packages\\django\\utils\\datastructures.py\", line 86, in __getitem__\n    raise MultiValueDictKeyError(key)\ndjango.utils.datastructures.MultiValueDictKeyError: 'pago'\n\nDuring handling of the above exception, another exception occurred:\n\nTraceback (most recent call last):\n  File \"C:\\Users\\Eliana Galban\\AccionesElBosque\\venv\\Lib\\site-packages\\django\\template\\base.py\", line 901, in _resolve_lookup\n    current = getattr(current, bit)\n              ^^^^^^^^^^^^^^^^^^^^^\nAttributeError: 'QueryDict' object has no attribute 'pago'\n\nDuring handling of the above exception, another exception occurred:\n\nTraceback (most recent call last):\n  File \"C:\\Users\\Eliana Galban\\AccionesElBosque\\venv\\Lib\\site-packages\\django\\template\\base.py\", line 907, in _resolve_lookup\n    current = current[int(bit)]\n                      ^^^^^^^^\nValueError: invalid literal for int() with base 10: 'pago'\n\nDuring handling of the above exception, another exception occurred:\n\nTraceback (most recent call last):\n  File \"C:\\Users\\Eliana Galban\\AccionesElBosque\\venv\\Lib\\site-packages\\django\\template\\base.py\", line 914, in _resolve_lookup\n    raise VariableDoesNotExist(\ndjango.template.base.VariableDoesNotExist: Failed lookup for key [pago] in <QueryDict: {}>"}
{"asctime": "2025-05-23 16:57:14,983", "levelname": "DEBUG", "name": "django.template", "module": "base", "funcName": "_resolve_lookup", "lineno": 941, "message": "Exception while resolving variable 'pago' in template 'accounts/perfil.html'.", "exc_info": "Traceback (most recent call last):\n  File \"C:\\Users\\Eliana Galban\\AccionesElBosque\\venv\\Lib\\site-packages\\django\\utils\\datastructures.py\", line 84, in __getitem__\n    list_ = super().__getitem__(key)\n            ^^^^^^^^^^^^^^^^^^^^^^^^\nKeyError: 'pago'\n\nDuring handling of the above exception, another exception occurred:\n\nTraceback (most recent call last):\n  File \"C:\\Users\\Eliana Galban\\AccionesElBosque\\venv\\Lib\\site-packages\\django\\template\\base.py\", line 891, in _resolve_lookup\n    current = current[bit]\n              ~~~~~~~^^^^^\n  File \"C:\\Users\\Eliana Galban\\AccionesElBosque\\venv\\Lib\\site-packages\\django\\utils\\datastructures.py\", line 86, in __getitem__\n    raise MultiValueDictKeyError(key)\ndjango.utils.datastructures.MultiValueDictKeyError: 'pago'\n\nDuring handling of the above exception, another exception occurred:\n\nTraceback (most recent call last):\n  File \"C:\\Users\\Eliana Galban\\AccionesElBosque\\venv\\Lib\\site-packages\\django\\template\\base.py\", line 901, in _resolve_lookup\n    current = getattr(current, bit)\n              ^^^^^^^^^^^^^^^^^^^^^\nAttributeError: 'QueryDict' object has no attribute 'pago'\n\nDuring handling of the above exception, another exception occurred:\n\nTraceback (most recent call last):\n  File \"C:\\Users\\Eliana Galban\\AccionesElBosque\\venv\\Lib\\site-packages\\django\\template\\base.py\", line 907, in _resolve_lookup\n    current = current[int(bit)]\n                      ^^^^^^^^\nValueError: invalid literal for int() with base 10: 'pago'\n\nDuring handling of the above exception, another exception occurred:\n\nTraceback (most recent call last):\n  File \"C:\\Users\\Eliana Galban\\AccionesElBosque\\venv\\Lib\\site-packages\\django\\template\\base.py\", line 914, in _resolve_lookup\n    raise VariableDoesNotExist(\ndjango.template.base.VariableDoesNotExist: Failed lookup for key [pago] in <QueryDict: {}>"}
{"asctime": "2025-05-23 16:59:53,563", "levelname": "DEBUG", "name": "django.template", "module": "base", "funcName": "_resolve_lookup", "lineno": 941, "message": "Exception while resolving variable 'pago' in template 'accounts/perfil.html'.", "exc_info": "Traceback (most recent call last):\n  File \"C:\\Users\\Eliana Galban\\AccionesElBosque\\venv\\Lib\\site-packages\\django\\utils\\datastructures.py\", line 84, in __getitem__\n    list_ = super().__getitem__(key)\n            ^^^^^^^^^^^^^^^^^^^^^^^^\nKeyError: 'pago'\n\nDuring handling of the above exception, another exception occurred:\n\nTraceback (most recent call last):\n  File \"C:\\Users\\Eliana Galban\\AccionesElBosque\\venv\\Lib\\site-packages\\django\\template\\base.py\", line 891, in _resolve_lookup\n    current = current[bit]\n              ~~~~~~~^^^^^\n  File \"C:\\Users\\Eliana Galban\\AccionesElBosque\\venv\\Lib\\site-packages\\django\\utils\\datastructures.py\", line 86, in __getitem__\n    raise MultiValueDictKeyError(key)\ndjango.utils.datastructures.MultiValueDictKeyError: 'pago'\n\nDuring handling of the above exception, another exception occurred:\n\nTraceback (most recent call last):\n  File \"C:\\Users\\Eliana Galban\\AccionesElBosque\\venv\\Lib\\site-packages\\django\\template\\base.py\", line 901, in _resolve_lookup\n    current = getattr(current, bit)\n              ^^^^^^^^^^^^^^^^^^^^^\nAttributeError: 'QueryDict' object has no attribute 'pago'\n\nDuring handling of the above exception, another exception occurred:\n\nTraceback (most recent call last):\n  File \"C:\\Users\\Eliana Galban\\AccionesElBosque\\venv\\Lib\\site-packages\\django\\template\\base.py\", line 907, in _resolve_lookup\n    current = current[int(bit)]\n                      ^^^^^^^^\nValueError: invalid literal for int() with base 10: 'pago'\n\nDuring handling of the above exception, another exception occurred:\n\nTraceback (most recent call last):\n  File \"C:\\Users\\Eliana Galban\\AccionesElBosque\\venv\\Lib\\site-packages\\django\\template\\base.py\", line 914, in _resolve_lookup\n    raise VariableDoesNotExist(\ndjango.template.base.VariableDoesNotExist: Failed lookup for key [pago] in <QueryDict: {}>"}
{"asctime": "2025-05-23 16:59:53,566", "levelname": "DEBUG", "name": "django.template", "module": "base", "funcName": "_resolve_lookup", "lineno": 941, "message": "Exception while resolving variable 'pago' in template 'accounts/perfil.html'.", "exc_info": "Traceback (most recent call last):\n  File \"C:\\Users\\Eliana Galban\\AccionesElBosque\\venv\\Lib\\site-packages\\django\\utils\\datastructures.py\", line 84, in __getitem__\n    list_ = super().__getitem__(key)\n            ^^^^^^^^^^^^^^^^^^^^^^^^\nKeyError: 'pago'\n\nDuring handling of the above exception, another exception occurred:\n\nTraceback (most recent call last):\n  File \"C:\\Users\\Eliana Galban\\AccionesElBosque\\venv\\Lib\\site-packages\\django\\template\\base.py\", line 891, in _resolve_lookup\n    current = current[bit]\n              ~~~~~~~^^^^^\n  File \"C:\\Users\\Eliana Galban\\AccionesElBosque\\venv\\Lib\\site-packages\\django\\utils\\datastructures.py\", line 86, in __getitem__\n    raise MultiValueDictKeyError(key)\ndjango.utils.datastructures.MultiValueDictKeyError: 'pago'\n\nDuring handling of the above exception, another exception occurred:\n\nTraceback (most recent call last):\n  File \"C:\\Users\\Eliana Galban\\AccionesElBosque\\venv\\Lib\\site-packages\\django\\template\\base.py\", line 901, in _resolve_lookup\n    current = getattr(current, bit)\n              ^^^^^^^^^^^^^^^^^^^^^\nAttributeError: 'QueryDict' object has no attribute 'pago'\n\nDuring handling of the above exception, another exception occurred:\n\nTraceback (most recent call last):\n  File \"C:\\Users\\Eliana Galban\\AccionesElBosque\\venv\\Lib\\site-packages\\django\\template\\base.py\", line 907, in _resolve_lookup\n    current = current[int(bit)]\n                      ^^^^^^^^\nValueError: invalid literal for int() with base 10: 'pago'\n\nDuring handling of the above exception, another exception occurred:\n\nTraceback (most recent call last):\n  File \"C:\\Users\\Eliana Galban\\AccionesElBosque\\venv\\Lib\\site-packages\\django\\template\\base.py\", line 914, in _resolve_lookup\n    raise VariableDoesNotExist(\ndjango.template.base.VariableDoesNotExist: Failed lookup for key [pago] in <QueryDict: {}>"}
{"asctime": "2025-05-23 17:38:03,257", "levelname": "DEBUG", "name": "django.template", "module": "base", "funcName": "_resolve_lookup", "lineno": 941, "message": "Exception while resolving variable 'pago' in template 'accounts/perfil.html'.", "exc_info": "Traceback (most recent call last):\n  File \"C:\\Users\\Eliana Galban\\AccionesElBosque\\venv\\Lib\\site-packages\\django\\utils\\datastructures.py\", line 84, in __getitem__\n    list_ = super().__getitem__(key)\n            ^^^^^^^^^^^^^^^^^^^^^^^^\nKeyError: 'pago'\n\nDuring handling of the above exception, another exception occurred:\n\nTraceback (most recent call last):\n  File \"C:\\Users\\Eliana Galban\\AccionesElBosque\\venv\\Lib\\site-packages\\django\\template\\base.py\", line 891, in _resolve_lookup\n    current = current[bit]\n              ~~~~~~~^^^^^\n  File \"C:\\Users\\Eliana Galban\\AccionesElBosque\\venv\\Lib\\site-packages\\django\\utils\\datastructures.py\", line 86, in __getitem__\n    raise MultiValueDictKeyError(key)\ndjango.utils.datastructures.MultiValueDictKeyError: 'pago'\n\nDuring handling of the above exception, another exception occurred:\n\nTraceback (most recent call last):\n  File \"C:\\Users\\Eliana Galban\\AccionesElBosque\\venv\\Lib\\site-packages\\django\\template\\base.py\", line 901, in _resolve_lookup\n    current = getattr(current, bit)\n              ^^^^^^^^^^^^^^^^^^^^^\nAttributeError: 'QueryDict' object has no attribute 'pago'\n\nDuring handling of the above exception, another exception occurred:\n\nTraceback (most recent call last):\n  File \"C:\\Users\\Eliana Galban\\AccionesElBosque\\venv\\Lib\\site-packages\\django\\template\\base.py\", line 907, in _resolve_lookup\n    current = current[int(bit)]\n                      ^^^^^^^^\nValueError: invalid literal for int() with base 10: 'pago'\n\nDuring handling of the above exception, another exception occurred:\n\nTraceback (most recent call last):\n  File \"C:\\Users\\Eliana Galban\\AccionesElBosque\\venv\\Lib\\site-packages\\django\\template\\base.py\", line 914, in _resolve_lookup\n    raise VariableDoesNotExist(\ndjango.template.base.VariableDoesNotExist: Failed lookup for key [pago] in <QueryDict: {}>"}
{"asctime": "2025-05-23 17:38:03,290", "levelname": "DEBUG", "name": "django.template", "module": "base", "funcName": "_resolve_lookup", "lineno": 941, "message": "Exception while resolving variable 'pago' in template 'accounts/perfil.html'.", "exc_info": "Traceback (most recent call last):\n  File \"C:\\Users\\Eliana Galban\\AccionesElBosque\\venv\\Lib\\site-packages\\django\\utils\\datastructures.py\", line 84, in __getitem__\n    list_ = super().__getitem__(key)\n            ^^^^^^^^^^^^^^^^^^^^^^^^\nKeyError: 'pago'\n\nDuring handling of the above exception, another exception occurred:\n\nTraceback (most recent call last):\n  File \"C:\\Users\\Eliana Galban\\AccionesElBosque\\venv\\Lib\\site-packages\\django\\template\\base.py\", line 891, in _resolve_lookup\n    current = current[bit]\n              ~~~~~~~^^^^^\n  File \"C:\\Users\\Eliana Galban\\AccionesElBosque\\venv\\Lib\\site-packages\\django\\utils\\datastructures.py\", line 86, in __getitem__\n    raise MultiValueDictKeyError(key)\ndjango.utils.datastructures.MultiValueDictKeyError: 'pago'\n\nDuring handling of the above exception, another exception occurred:\n\nTraceback (most recent call last):\n  File \"C:\\Users\\Eliana Galban\\AccionesElBosque\\venv\\Lib\\site-packages\\django\\template\\base.py\", line 901, in _resolve_lookup\n    current = getattr(current, bit)\n              ^^^^^^^^^^^^^^^^^^^^^\nAttributeError: 'QueryDict' object has no attribute 'pago'\n\nDuring handling of the above exception, another exception occurred:\n\nTraceback (most recent call last):\n  File \"C:\\Users\\Eliana Galban\\AccionesElBosque\\venv\\Lib\\site-packages\\django\\template\\base.py\", line 907, in _resolve_lookup\n    current = current[int(bit)]\n                      ^^^^^^^^\nValueError: invalid literal for int() with base 10: 'pago'\n\nDuring handling of the above exception, another exception occurred:\n\nTraceback (most recent call last):\n  File \"C:\\Users\\Eliana Galban\\AccionesElBosque\\venv\\Lib\\site-packages\\django\\template\\base.py\", line 914, in _resolve_lookup\n    raise VariableDoesNotExist(\ndjango.template.base.VariableDoesNotExist: Failed lookup for key [pago] in <QueryDict: {}>"}
{"asctime": "2025-05-23 17:38:04,473", "levelname": "DEBUG", "name": "django.template", "module": "base", "funcName": "_resolve_lookup", "lineno": 941, "message": "Exception while resolving variable 'pago' in template 'accounts/perfil.html'.", "exc_info": "Traceback (most recent call last):\n  File \"C:\\Users\\Eliana Galban\\AccionesElBosque\\venv\\Lib\\site-packages\\django\\utils\\datastructures.py\", line 84, in __getitem__\n    list_ = super().__getitem__(key)\n            ^^^^^^^^^^^^^^^^^^^^^^^^\nKeyError: 'pago'\n\nDuring handling of the above exception, another exception occurred:\n\nTraceback (most recent call last):\n  File \"C:\\Users\\Eliana Galban\\AccionesElBosque\\venv\\Lib\\site-packages\\django\\template\\base.py\", line 891, in _resolve_lookup\n    current = current[bit]\n              ~~~~~~~^^^^^\n  File \"C:\\Users\\Eliana Galban\\AccionesElBosque\\venv\\Lib\\site-packages\\django\\utils\\datastructures.py\", line 86, in __getitem__\n    raise MultiValueDictKeyError(key)\ndjango.utils.datastructures.MultiValueDictKeyError: 'pago'\n\nDuring handling of the above exception, another exception occurred:\n\nTraceback (most recent call last):\n  File \"C:\\Users\\Eliana Galban\\AccionesElBosque\\venv\\Lib\\site-packages\\django\\template\\base.py\", line 901, in _resolve_lookup\n    current = getattr(current, bit)\n              ^^^^^^^^^^^^^^^^^^^^^\nAttributeError: 'QueryDict' object has no attribute 'pago'\n\nDuring handling of the above exception, another exception occurred:\n\nTraceback (most recent call last):\n  File \"C:\\Users\\Eliana Galban\\AccionesElBosque\\venv\\Lib\\site-packages\\django\\template\\base.py\", line 907, in _resolve_lookup\n    current = current[int(bit)]\n                      ^^^^^^^^\nValueError: invalid literal for int() with base 10: 'pago'\n\nDuring handling of the above exception, another exception occurred:\n\nTraceback (most recent call last):\n  File \"C:\\Users\\Eliana Galban\\AccionesElBosque\\venv\\Lib\\site-packages\\django\\template\\base.py\", line 914, in _resolve_lookup\n    raise VariableDoesNotExist(\ndjango.template.base.VariableDoesNotExist: Failed lookup for key [pago] in <QueryDict: {}>"}
{"asctime": "2025-05-23 17:38:04,474", "levelname": "DEBUG", "name": "django.template", "module": "base", "funcName": "_resolve_lookup", "lineno": 941, "message": "Exception while resolving variable 'pago' in template 'accounts/perfil.html'.", "exc_info": "Traceback (most recent call last):\n  File \"C:\\Users\\Eliana Galban\\AccionesElBosque\\venv\\Lib\\site-packages\\django\\utils\\datastructures.py\", line 84, in __getitem__\n    list_ = super().__getitem__(key)\n            ^^^^^^^^^^^^^^^^^^^^^^^^\nKeyError: 'pago'\n\nDuring handling of the above exception, another exception occurred:\n\nTraceback (most recent call last):\n  File \"C:\\Users\\Eliana Galban\\AccionesElBosque\\venv\\Lib\\site-packages\\django\\template\\base.py\", line 891, in _resolve_lookup\n    current = current[bit]\n              ~~~~~~~^^^^^\n  File \"C:\\Users\\Eliana Galban\\AccionesElBosque\\venv\\Lib\\site-packages\\django\\utils\\datastructures.py\", line 86, in __getitem__\n    raise MultiValueDictKeyError(key)\ndjango.utils.datastructures.MultiValueDictKeyError: 'pago'\n\nDuring handling of the above exception, another exception occurred:\n\nTraceback (most recent call last):\n  File \"C:\\Users\\Eliana Galban\\AccionesElBosque\\venv\\Lib\\site-packages\\django\\template\\base.py\", line 901, in _resolve_lookup\n    current = getattr(current, bit)\n              ^^^^^^^^^^^^^^^^^^^^^\nAttributeError: 'QueryDict' object has no attribute 'pago'\n\nDuring handling of the above exception, another exception occurred:\n\nTraceback (most recent call last):\n  File \"C:\\Users\\Eliana Galban\\AccionesElBosque\\venv\\Lib\\site-packages\\django\\template\\base.py\", line 907, in _resolve_lookup\n    current = current[int(bit)]\n                      ^^^^^^^^\nValueError: invalid literal for int() with base 10: 'pago'\n\nDuring handling of the above exception, another exception occurred:\n\nTraceback (most recent call last):\n  File \"C:\\Users\\Eliana Galban\\AccionesElBosque\\venv\\Lib\\site-packages\\django\\template\\base.py\", line 914, in _resolve_lookup\n    raise VariableDoesNotExist(\ndjango.template.base.VariableDoesNotExist: Failed lookup for key [pago] in <QueryDict: {}>"}
{"asctime": "2025-05-25 14:00:03,421", "levelname": "DEBUG", "name": "django.template", "module": "base", "funcName": "_resolve_lookup", "lineno": 941, "message": "Exception while resolving variable 'saldo' in template 'trading/portafolio.html'.", "exc_info": "Traceback (most recent call last):\n  File \"C:\\Users\\Eliana Galban\\AccionesElBosque\\venv\\Lib\\site-packages\\django\\template\\base.py\", line 891, in _resolve_lookup\n    current = current[bit]\n              ~~~~~~~^^^^^\n  File \"C:\\Users\\Eliana Galban\\AccionesElBosque\\venv\\Lib\\site-packages\\django\\template\\context.py\", line 88, in __getitem__\n    raise KeyError(key)\nKeyError: 'saldo'\n\nDuring handling of the above exception, another exception occurred:\n\nTraceback (most recent call last):\n  File \"C:\\Users\\Eliana Galban\\AccionesElBosque\\venv\\Lib\\site-packages\\django\\template\\base.py\", line 897, in _resolve_lookup\n    if isinstance(current, BaseContext) and getattr(\n                                            ^^^^^^^^\nAttributeError: type object 'RequestContext' has no attribute 'saldo'\n\nDuring handling of the above exception, another exception occurred:\n\nTraceback (most recent call last):\n  File \"C:\\Users\\Eliana Galban\\AccionesElBosque\\venv\\Lib\\site-packages\\django\\template\\base.py\", line 907, in _resolve_lookup\n    current = current[int(bit)]\n                      ^^^^^^^^\nValueError: invalid literal for int() with base 10: 'saldo'\n\nDuring handling of the above exception, another exception occurred:\n\nTraceback (most recent call last):\n  File \"C:\\Users\\Eliana Galban\\AccionesElBosque\\venv\\Lib\\site-packages\\django\\template\\base.py\", line 914, in _resolve_lookup\n    raise VariableDoesNotExist(\ndjango.template.base.VariableDoesNotExist: Failed lookup for key [saldo] in [{'True': True, 'False': False, 'None': None}, {'csrf_token': <SimpleLazyObject: <function csrf.<locals>._get_val at 0x000001EB49594180>>, 'request': <WSGIRequest: GET '/trading/portafolio/'>, 'user': <SimpleLazyObject: <function AuthenticationMiddleware.process_request.<locals>.<lambda> at 0x000001EB49594220>>, 'perms': PermWrapper(<SimpleLazyObject: <function AuthenticationMiddleware.process_request.<locals>.<lambda> at 0x000001EB49594220>>), 'messages': <FallbackStorage: request=<WSGIRequest: GET '/trading/portafolio/'>>, 'DEFAULT_MESSAGE_LEVELS': {'DEBUG': 10, 'INFO': 20, 'SUCCESS': 25, 'WARNING': 30, 'ERROR': 40}}, {}, {'portafolio': []}]"}
{"asctime": "2025-05-25 14:11:21,599", "levelname": "DEBUG", "name": "django.template", "module": "base", "funcName": "_resolve_lookup", "lineno": 941, "message": "Exception while resolving variable 'saldo' in template 'trading/portafolio.html'.", "exc_info": "Traceback (most recent call last):\n  File \"C:\\Users\\Eliana Galban\\AccionesElBosque\\venv\\Lib\\site-packages\\django\\template\\base.py\", line 891, in _resolve_lookup\n    current = current[bit]\n              ~~~~~~~^^^^^\n  File \"C:\\Users\\Eliana Galban\\AccionesElBosque\\venv\\Lib\\site-packages\\django\\template\\context.py\", line 88, in __getitem__\n    raise KeyError(key)\nKeyError: 'saldo'\n\nDuring handling of the above exception, another exception occurred:\n\nTraceback (most recent call last):\n  File \"C:\\Users\\Eliana Galban\\AccionesElBosque\\venv\\Lib\\site-packages\\django\\template\\base.py\", line 897, in _resolve_lookup\n    if isinstance(current, BaseContext) and getattr(\n                                            ^^^^^^^^\nAttributeError: type object 'RequestContext' has no attribute 'saldo'\n\nDuring handling of the above exception, another exception occurred:\n\nTraceback (most recent call last):\n  File \"C:\\Users\\Eliana Galban\\AccionesElBosque\\venv\\Lib\\site-packages\\django\\template\\base.py\", line 907, in _resolve_lookup\n    current = current[int(bit)]\n                      ^^^^^^^^\nValueError: invalid literal for int() with base 10: 'saldo'\n\nDuring handling of the above exception, another exception occurred:\n\nTraceback (most recent call last):\n  File \"C:\\Users\\Eliana Galban\\AccionesElBosque\\venv\\Lib\\site-packages\\django\\template\\base.py\", line 914, in _resolve_lookup\n    raise VariableDoesNotExist(\ndjango.template.base.VariableDoesNotExist: Failed lookup for key [saldo] in [{'True': True, 'False': False, 'None': None}, {'csrf_token': <SimpleLazyObject: <function csrf.<locals>._get_val at 0x000001EB495947C0>>, 'request': <WSGIRequest: GET '/trading/portafolio/'>, 'user': <SimpleLazyObject: <function AuthenticationMiddleware.process_request.<locals>.<lambda> at 0x000001EB49594860>>, 'perms': PermWrapper(<SimpleLazyObject: <function AuthenticationMiddleware.process_request.<locals>.<lambda> at 0x000001EB49594860>>), 'messages': <FallbackStorage: request=<WSGIRequest: GET '/trading/portafolio/'>>, 'DEFAULT_MESSAGE_LEVELS': {'DEBUG': 10, 'INFO': 20, 'SUCCESS': 25, 'WARNING': 30, 'ERROR': 40}}, {}, {'portafolio': []}]"}
{"asctime": "2025-05-25 14:12:11,601", "levelname": "DEBUG", "name": "django.template", "module": "base", "funcName": "_resolve_lookup", "lineno": 941, "message": "Exception while resolving variable 'saldo' in template 'trading/portafolio.html'.", "exc_info": "Traceback (most recent call last):\n  File \"C:\\Users\\Eliana Galban\\AccionesElBosque\\venv\\Lib\\site-packages\\django\\template\\base.py\", line 891, in _resolve_lookup\n    current = current[bit]\n              ~~~~~~~^^^^^\n  File \"C:\\Users\\Eliana Galban\\AccionesElBosque\\venv\\Lib\\site-packages\\django\\template\\context.py\", line 88, in __getitem__\n    raise KeyError(key)\nKeyError: 'saldo'\n\nDuring handling of the above exception, another exception occurred:\n\nTraceback (most recent call last):\n  File \"C:\\Users\\Eliana Galban\\AccionesElBosque\\venv\\Lib\\site-packages\\django\\template\\base.py\", line 897, in _resolve_lookup\n    if isinstance(current, BaseContext) and getattr(\n                                            ^^^^^^^^\nAttributeError: type object 'RequestContext' has no attribute 'saldo'\n\nDuring handling of the above exception, another exception occurred:\n\nTraceback (most recent call last):\n  File \"C:\\Users\\Eliana Galban\\AccionesElBosque\\venv\\Lib\\site-packages\\django\\template\\base.py\", line 907, in _resolve_lookup\n    current = current[int(bit)]\n                      ^^^^^^^^\nValueError: invalid literal for int() with base 10: 'saldo'\n\nDuring handling of the above exception, another exception occurred:\n\nTraceback (most recent call last):\n  File \"C:\\Users\\Eliana Galban\\AccionesElBosque\\venv\\Lib\\site-packages\\django\\template\\base.py\", line 914, in _resolve_lookup\n    raise VariableDoesNotExist(\ndjango.template.base.VariableDoesNotExist: Failed lookup for key [saldo] in [{'True': True, 'False': False, 'None': None}, {'csrf_token': <SimpleLazyObject: <function csrf.<locals>._get_val at 0x000001EB49594CC0>>, 'request': <WSGIRequest: GET '/trading/portafolio/'>, 'user': <SimpleLazyObject: <function AuthenticationMiddleware.process_request.<locals>.<lambda> at 0x000001EB49595300>>, 'perms': PermWrapper(<SimpleLazyObject: <function AuthenticationMiddleware.process_request.<locals>.<lambda> at 0x000001EB49595300>>), 'messages': <FallbackStorage: request=<WSGIRequest: GET '/trading/portafolio/'>>, 'DEFAULT_MESSAGE_LEVELS': {'DEBUG': 10, 'INFO': 20, 'SUCCESS': 25, 'WARNING': 30, 'ERROR': 40}}, {}, {'portafolio': []}]"}
{"asctime": "2025-05-25 14:12:18,196", "levelname": "DEBUG", "name": "django.template", "module": "base", "funcName": "_resolve_lookup", "lineno": 941, "message": "Exception while resolving variable 'saldo' in template 'trading/portafolio.html'.", "exc_info": "Traceback (most recent call last):\n  File \"C:\\Users\\Eliana Galban\\AccionesElBosque\\venv\\Lib\\site-packages\\django\\template\\base.py\", line 891, in _resolve_lookup\n    current = current[bit]\n              ~~~~~~~^^^^^\n  File \"C:\\Users\\Eliana Galban\\AccionesElBosque\\venv\\Lib\\site-packages\\django\\template\\context.py\", line 88, in __getitem__\n    raise KeyError(key)\nKeyError: 'saldo'\n\nDuring handling of the above exception, another exception occurred:\n\nTraceback (most recent call last):\n  File \"C:\\Users\\Eliana Galban\\AccionesElBosque\\venv\\Lib\\site-packages\\django\\template\\base.py\", line 897, in _resolve_lookup\n    if isinstance(current, BaseContext) and getattr(\n                                            ^^^^^^^^\nAttributeError: type object 'RequestContext' has no attribute 'saldo'\n\nDuring handling of the above exception, another exception occurred:\n\nTraceback (most recent call last):\n  File \"C:\\Users\\Eliana Galban\\AccionesElBosque\\venv\\Lib\\site-packages\\django\\template\\base.py\", line 907, in _resolve_lookup\n    current = current[int(bit)]\n                      ^^^^^^^^\nValueError: invalid literal for int() with base 10: 'saldo'\n\nDuring handling of the above exception, another exception occurred:\n\nTraceback (most recent call last):\n  File \"C:\\Users\\Eliana Galban\\AccionesElBosque\\venv\\Lib\\site-packages\\django\\template\\base.py\", line 914, in _resolve_lookup\n    raise VariableDoesNotExist(\ndjango.template.base.VariableDoesNotExist: Failed lookup for key [saldo] in [{'True': True, 'False': False, 'None': None}, {'csrf_token': <SimpleLazyObject: <function csrf.<locals>._get_val at 0x000001EB495954E0>>, 'request': <WSGIRequest: GET '/trading/portafolio/'>, 'user': <SimpleLazyObject: <function AuthenticationMiddleware.process_request.<locals>.<lambda> at 0x000001EB49594400>>, 'perms': PermWrapper(<SimpleLazyObject: <function AuthenticationMiddleware.process_request.<locals>.<lambda> at 0x000001EB49594400>>), 'messages': <FallbackStorage: request=<WSGIRequest: GET '/trading/portafolio/'>>, 'DEFAULT_MESSAGE_LEVELS': {'DEBUG': 10, 'INFO': 20, 'SUCCESS': 25, 'WARNING': 30, 'ERROR': 40}}, {}, {'portafolio': []}]"}
{"asctime": "2025-05-25 14:14:06,271", "levelname": "DEBUG", "name": "django.template", "module": "base", "funcName": "_resolve_lookup", "lineno": 941, "message": "Exception while resolving variable 'saldo' in template 'trading/portafolio.html'.", "exc_info": "Traceback (most recent call last):\n  File \"C:\\Users\\Eliana Galban\\AccionesElBosque\\venv\\Lib\\site-packages\\django\\template\\base.py\", line 891, in _resolve_lookup\n    current = current[bit]\n              ~~~~~~~^^^^^\n  File \"C:\\Users\\Eliana Galban\\AccionesElBosque\\venv\\Lib\\site-packages\\django\\template\\context.py\", line 88, in __getitem__\n    raise KeyError(key)\nKeyError: 'saldo'\n\nDuring handling of the above exception, another exception occurred:\n\nTraceback (most recent call last):\n  File \"C:\\Users\\Eliana Galban\\AccionesElBosque\\venv\\Lib\\site-packages\\django\\template\\base.py\", line 897, in _resolve_lookup\n    if isinstance(current, BaseContext) and getattr(\n                                            ^^^^^^^^\nAttributeError: type object 'RequestContext' has no attribute 'saldo'\n\nDuring handling of the above exception, another exception occurred:\n\nTraceback (most recent call last):\n  File \"C:\\Users\\Eliana Galban\\AccionesElBosque\\venv\\Lib\\site-packages\\django\\template\\base.py\", line 907, in _resolve_lookup\n    current = current[int(bit)]\n                      ^^^^^^^^\nValueError: invalid literal for int() with base 10: 'saldo'\n\nDuring handling of the above exception, another exception occurred:\n\nTraceback (most recent call last):\n  File \"C:\\Users\\Eliana Galban\\AccionesElBosque\\venv\\Lib\\site-packages\\django\\template\\base.py\", line 914, in _resolve_lookup\n    raise VariableDoesNotExist(\ndjango.template.base.VariableDoesNotExist: Failed lookup for key [saldo] in [{'True': True, 'False': False, 'None': None}, {'csrf_token': <SimpleLazyObject: <function csrf.<locals>._get_val at 0x000001EB495944A0>>, 'request': <WSGIRequest: GET '/trading/portafolio/'>, 'user': <SimpleLazyObject: <function AuthenticationMiddleware.process_request.<locals>.<lambda> at 0x000001EB495953A0>>, 'perms': PermWrapper(<SimpleLazyObject: <function AuthenticationMiddleware.process_request.<locals>.<lambda> at 0x000001EB495953A0>>), 'messages': <FallbackStorage: request=<WSGIRequest: GET '/trading/portafolio/'>>, 'DEFAULT_MESSAGE_LEVELS': {'DEBUG': 10, 'INFO': 20, 'SUCCESS': 25, 'WARNING': 30, 'ERROR': 40}}, {}, {'portafolio': []}]"}
{"asctime": "2025-05-25 14:14:45,408", "levelname": "DEBUG", "name": "django.template", "module": "base", "funcName": "_resolve_lookup", "lineno": 941, "message": "Exception while resolving variable 'saldo' in template 'trading/portafolio.html'.", "exc_info": "Traceback (most recent call last):\n  File \"C:\\Users\\Eliana Galban\\AccionesElBosque\\venv\\Lib\\site-packages\\django\\template\\base.py\", line 891, in _resolve_lookup\n    current = current[bit]\n              ~~~~~~~^^^^^\n  File \"C:\\Users\\Eliana Galban\\AccionesElBosque\\venv\\Lib\\site-packages\\django\\template\\context.py\", line 88, in __getitem__\n    raise KeyError(key)\nKeyError: 'saldo'\n\nDuring handling of the above exception, another exception occurred:\n\nTraceback (most recent call last):\n  File \"C:\\Users\\Eliana Galban\\AccionesElBosque\\venv\\Lib\\site-packages\\django\\template\\base.py\", line 897, in _resolve_lookup\n    if isinstance(current, BaseContext) and getattr(\n                                            ^^^^^^^^\nAttributeError: type object 'RequestContext' has no attribute 'saldo'\n\nDuring handling of the above exception, another exception occurred:\n\nTraceback (most recent call last):\n  File \"C:\\Users\\Eliana Galban\\AccionesElBosque\\venv\\Lib\\site-packages\\django\\template\\base.py\", line 907, in _resolve_lookup\n    current = current[int(bit)]\n                      ^^^^^^^^\nValueError: invalid literal for int() with base 10: 'saldo'\n\nDuring handling of the above exception, another exception occurred:\n\nTraceback (most recent call last):\n  File \"C:\\Users\\Eliana Galban\\AccionesElBosque\\venv\\Lib\\site-packages\\django\\template\\base.py\", line 914, in _resolve_lookup\n    raise VariableDoesNotExist(\ndjango.template.base.VariableDoesNotExist: Failed lookup for key [saldo] in [{'True': True, 'False': False, 'None': None}, {'csrf_token': <SimpleLazyObject: <function csrf.<locals>._get_val at 0x000001EB49594FE0>>, 'request': <WSGIRequest: GET '/trading/portafolio/'>, 'user': <SimpleLazyObject: <function AuthenticationMiddleware.process_request.<locals>.<lambda> at 0x000001EB49594360>>, 'perms': PermWrapper(<SimpleLazyObject: <function AuthenticationMiddleware.process_request.<locals>.<lambda> at 0x000001EB49594360>>), 'messages': <FallbackStorage: request=<WSGIRequest: GET '/trading/portafolio/'>>, 'DEFAULT_MESSAGE_LEVELS': {'DEBUG': 10, 'INFO': 20, 'SUCCESS': 25, 'WARNING': 30, 'ERROR': 40}}, {}, {'portafolio': []}]"}
{"asctime": "2025-05-25 14:15:11,060", "levelname": "DEBUG", "name": "django.template", "module": "base", "funcName": "_resolve_lookup", "lineno": 941, "message": "Exception while resolving variable 'saldo' in template 'trading/portafolio.html'.", "exc_info": "Traceback (most recent call last):\n  File \"C:\\Users\\Eliana Galban\\AccionesElBosque\\venv\\Lib\\site-packages\\django\\template\\base.py\", line 891, in _resolve_lookup\n    current = current[bit]\n              ~~~~~~~^^^^^\n  File \"C:\\Users\\Eliana Galban\\AccionesElBosque\\venv\\Lib\\site-packages\\django\\template\\context.py\", line 88, in __getitem__\n    raise KeyError(key)\nKeyError: 'saldo'\n\nDuring handling of the above exception, another exception occurred:\n\nTraceback (most recent call last):\n  File \"C:\\Users\\Eliana Galban\\AccionesElBosque\\venv\\Lib\\site-packages\\django\\template\\base.py\", line 897, in _resolve_lookup\n    if isinstance(current, BaseContext) and getattr(\n                                            ^^^^^^^^\nAttributeError: type object 'RequestContext' has no attribute 'saldo'\n\nDuring handling of the above exception, another exception occurred:\n\nTraceback (most recent call last):\n  File \"C:\\Users\\Eliana Galban\\AccionesElBosque\\venv\\Lib\\site-packages\\django\\template\\base.py\", line 907, in _resolve_lookup\n    current = current[int(bit)]\n                      ^^^^^^^^\nValueError: invalid literal for int() with base 10: 'saldo'\n\nDuring handling of the above exception, another exception occurred:\n\nTraceback (most recent call last):\n  File \"C:\\Users\\Eliana Galban\\AccionesElBosque\\venv\\Lib\\site-packages\\django\\template\\base.py\", line 914, in _resolve_lookup\n    raise VariableDoesNotExist(\ndjango.template.base.VariableDoesNotExist: Failed lookup for key [saldo] in [{'True': True, 'False': False, 'None': None}, {'csrf_token': <SimpleLazyObject: <function csrf.<locals>._get_val at 0x000001EB4965E980>>, 'request': <WSGIRequest: GET '/trading/portafolio/'>, 'user': <SimpleLazyObject: <function AuthenticationMiddleware.process_request.<locals>.<lambda> at 0x000001EB49594CC0>>, 'perms': PermWrapper(<SimpleLazyObject: <function AuthenticationMiddleware.process_request.<locals>.<lambda> at 0x000001EB49594CC0>>), 'messages': <FallbackStorage: request=<WSGIRequest: GET '/trading/portafolio/'>>, 'DEFAULT_MESSAGE_LEVELS': {'DEBUG': 10, 'INFO': 20, 'SUCCESS': 25, 'WARNING': 30, 'ERROR': 40}}, {}, {'portafolio': []}]"}
{"asctime": "2025-05-25 14:16:07,777", "levelname": "DEBUG", "name": "django.template", "module": "base", "funcName": "_resolve_lookup", "lineno": 941, "message": "Exception while resolving variable 'saldo' in template 'trading/portafolio.html'.", "exc_info": "Traceback (most recent call last):\n  File \"C:\\Users\\Eliana Galban\\AccionesElBosque\\venv\\Lib\\site-packages\\django\\template\\base.py\", line 891, in _resolve_lookup\n    current = current[bit]\n              ~~~~~~~^^^^^\n  File \"C:\\Users\\Eliana Galban\\AccionesElBosque\\venv\\Lib\\site-packages\\django\\template\\context.py\", line 88, in __getitem__\n    raise KeyError(key)\nKeyError: 'saldo'\n\nDuring handling of the above exception, another exception occurred:\n\nTraceback (most recent call last):\n  File \"C:\\Users\\Eliana Galban\\AccionesElBosque\\venv\\Lib\\site-packages\\django\\template\\base.py\", line 897, in _resolve_lookup\n    if isinstance(current, BaseContext) and getattr(\n                                            ^^^^^^^^\nAttributeError: type object 'RequestContext' has no attribute 'saldo'\n\nDuring handling of the above exception, another exception occurred:\n\nTraceback (most recent call last):\n  File \"C:\\Users\\Eliana Galban\\AccionesElBosque\\venv\\Lib\\site-packages\\django\\template\\base.py\", line 907, in _resolve_lookup\n    current = current[int(bit)]\n                      ^^^^^^^^\nValueError: invalid literal for int() with base 10: 'saldo'\n\nDuring handling of the above exception, another exception occurred:\n\nTraceback (most recent call last):\n  File \"C:\\Users\\Eliana Galban\\AccionesElBosque\\venv\\Lib\\site-packages\\django\\template\\base.py\", line 914, in _resolve_lookup\n    raise VariableDoesNotExist(\ndjango.template.base.VariableDoesNotExist: Failed lookup for key [saldo] in [{'True': True, 'False': False, 'None': None}, {'csrf_token': <SimpleLazyObject: <function csrf.<locals>._get_val at 0x000001EB49597BA0>>, 'request': <WSGIRequest: GET '/trading/portafolio/'>, 'user': <SimpleLazyObject: <function AuthenticationMiddleware.process_request.<locals>.<lambda> at 0x000001EB4965E980>>, 'perms': PermWrapper(<SimpleLazyObject: <function AuthenticationMiddleware.process_request.<locals>.<lambda> at 0x000001EB4965E980>>), 'messages': <FallbackStorage: request=<WSGIRequest: GET '/trading/portafolio/'>>, 'DEFAULT_MESSAGE_LEVELS': {'DEBUG': 10, 'INFO': 20, 'SUCCESS': 25, 'WARNING': 30, 'ERROR': 40}}, {}, {'portafolio': []}]"}
{"asctime": "2025-05-25 14:16:30,440", "levelname": "DEBUG", "name": "django.template", "module": "base", "funcName": "_resolve_lookup", "lineno": 941, "message": "Exception while resolving variable 'saldo' in template 'trading/portafolio.html'.", "exc_info": "Traceback (most recent call last):\n  File \"C:\\Users\\Eliana Galban\\AccionesElBosque\\venv\\Lib\\site-packages\\django\\template\\base.py\", line 891, in _resolve_lookup\n    current = current[bit]\n              ~~~~~~~^^^^^\n  File \"C:\\Users\\Eliana Galban\\AccionesElBosque\\venv\\Lib\\site-packages\\django\\template\\context.py\", line 88, in __getitem__\n    raise KeyError(key)\nKeyError: 'saldo'\n\nDuring handling of the above exception, another exception occurred:\n\nTraceback (most recent call last):\n  File \"C:\\Users\\Eliana Galban\\AccionesElBosque\\venv\\Lib\\site-packages\\django\\template\\base.py\", line 897, in _resolve_lookup\n    if isinstance(current, BaseContext) and getattr(\n                                            ^^^^^^^^\nAttributeError: type object 'RequestContext' has no attribute 'saldo'\n\nDuring handling of the above exception, another exception occurred:\n\nTraceback (most recent call last):\n  File \"C:\\Users\\Eliana Galban\\AccionesElBosque\\venv\\Lib\\site-packages\\django\\template\\base.py\", line 907, in _resolve_lookup\n    current = current[int(bit)]\n                      ^^^^^^^^\nValueError: invalid literal for int() with base 10: 'saldo'\n\nDuring handling of the above exception, another exception occurred:\n\nTraceback (most recent call last):\n  File \"C:\\Users\\Eliana Galban\\AccionesElBosque\\venv\\Lib\\site-packages\\django\\template\\base.py\", line 914, in _resolve_lookup\n    raise VariableDoesNotExist(\ndjango.template.base.VariableDoesNotExist: Failed lookup for key [saldo] in [{'True': True, 'False': False, 'None': None}, {'csrf_token': <SimpleLazyObject: <function csrf.<locals>._get_val at 0x000001EB495956C0>>, 'request': <WSGIRequest: GET '/trading/portafolio/'>, 'user': <SimpleLazyObject: <function AuthenticationMiddleware.process_request.<locals>.<lambda> at 0x000001EB495954E0>>, 'perms': PermWrapper(<SimpleLazyObject: <function AuthenticationMiddleware.process_request.<locals>.<lambda> at 0x000001EB495954E0>>), 'messages': <FallbackStorage: request=<WSGIRequest: GET '/trading/portafolio/'>>, 'DEFAULT_MESSAGE_LEVELS': {'DEBUG': 10, 'INFO': 20, 'SUCCESS': 25, 'WARNING': 30, 'ERROR': 40}}, {}, {'portafolio': []}]"}
{"asctime": "2025-05-25 14:19:15,012", "levelname": "DEBUG", "name": "django.template", "module": "base", "funcName": "_resolve_lookup", "lineno": 941, "message": "Exception while resolving variable 'saldo' in template 'trading/portafolio.html'.", "exc_info": "Traceback (most recent call last):\n  File \"C:\\Users\\Eliana Galban\\AccionesElBosque\\venv\\Lib\\site-packages\\django\\template\\base.py\", line 891, in _resolve_lookup\n    current = current[bit]\n              ~~~~~~~^^^^^\n  File \"C:\\Users\\Eliana Galban\\AccionesElBosque\\venv\\Lib\\site-packages\\django\\template\\context.py\", line 88, in __getitem__\n    raise KeyError(key)\nKeyError: 'saldo'\n\nDuring handling of the above exception, another exception occurred:\n\nTraceback (most recent call last):\n  File \"C:\\Users\\Eliana Galban\\AccionesElBosque\\venv\\Lib\\site-packages\\django\\template\\base.py\", line 897, in _resolve_lookup\n    if isinstance(current, BaseContext) and getattr(\n                                            ^^^^^^^^\nAttributeError: type object 'RequestContext' has no attribute 'saldo'\n\nDuring handling of the above exception, another exception occurred:\n\nTraceback (most recent call last):\n  File \"C:\\Users\\Eliana Galban\\AccionesElBosque\\venv\\Lib\\site-packages\\django\\template\\base.py\", line 907, in _resolve_lookup\n    current = current[int(bit)]\n                      ^^^^^^^^\nValueError: invalid literal for int() with base 10: 'saldo'\n\nDuring handling of the above exception, another exception occurred:\n\nTraceback (most recent call last):\n  File \"C:\\Users\\Eliana Galban\\AccionesElBosque\\venv\\Lib\\site-packages\\django\\template\\base.py\", line 914, in _resolve_lookup\n    raise VariableDoesNotExist(\ndjango.template.base.VariableDoesNotExist: Failed lookup for key [saldo] in [{'True': True, 'False': False, 'None': None}, {'csrf_token': <SimpleLazyObject: <function csrf.<locals>._get_val at 0x000001EB49595A80>>, 'request': <WSGIRequest: GET '/trading/portafolio/'>, 'user': <SimpleLazyObject: <function AuthenticationMiddleware.process_request.<locals>.<lambda> at 0x000001EB49594D60>>, 'perms': PermWrapper(<SimpleLazyObject: <function AuthenticationMiddleware.process_request.<locals>.<lambda> at 0x000001EB49594D60>>), 'messages': <FallbackStorage: request=<WSGIRequest: GET '/trading/portafolio/'>>, 'DEFAULT_MESSAGE_LEVELS': {'DEBUG': 10, 'INFO': 20, 'SUCCESS': 25, 'WARNING': 30, 'ERROR': 40}}, {}, {'portafolio': []}]"}
{"asctime": "2025-05-25 14:31:20,027", "levelname": "DEBUG", "name": "django.template", "module": "base", "funcName": "_resolve_lookup", "lineno": 941, "message": "Exception while resolving variable 'saldo' in template 'trading/portafolio.html'.", "exc_info": "Traceback (most recent call last):\n  File \"C:\\Users\\Eliana Galban\\AccionesElBosque\\venv\\Lib\\site-packages\\django\\template\\base.py\", line 891, in _resolve_lookup\n    current = current[bit]\n              ~~~~~~~^^^^^\n  File \"C:\\Users\\Eliana Galban\\AccionesElBosque\\venv\\Lib\\site-packages\\django\\template\\context.py\", line 88, in __getitem__\n    raise KeyError(key)\nKeyError: 'saldo'\n\nDuring handling of the above exception, another exception occurred:\n\nTraceback (most recent call last):\n  File \"C:\\Users\\Eliana Galban\\AccionesElBosque\\venv\\Lib\\site-packages\\django\\template\\base.py\", line 897, in _resolve_lookup\n    if isinstance(current, BaseContext) and getattr(\n                                            ^^^^^^^^\nAttributeError: type object 'RequestContext' has no attribute 'saldo'\n\nDuring handling of the above exception, another exception occurred:\n\nTraceback (most recent call last):\n  File \"C:\\Users\\Eliana Galban\\AccionesElBosque\\venv\\Lib\\site-packages\\django\\template\\base.py\", line 907, in _resolve_lookup\n    current = current[int(bit)]\n                      ^^^^^^^^\nValueError: invalid literal for int() with base 10: 'saldo'\n\nDuring handling of the above exception, another exception occurred:\n\nTraceback (most recent call last):\n  File \"C:\\Users\\Eliana Galban\\AccionesElBosque\\venv\\Lib\\site-packages\\django\\template\\base.py\", line 914, in _resolve_lookup\n    raise VariableDoesNotExist(\ndjango.template.base.VariableDoesNotExist: Failed lookup for key [saldo] in [{'True': True, 'False': False, 'None': None}, {'csrf_token': <SimpleLazyObject: <function csrf.<locals>._get_val at 0x000002816144DA80>>, 'request': <WSGIRequest: GET '/trading/portafolio/'>, 'user': <SimpleLazyObject: <function AuthenticationMiddleware.process_request.<locals>.<lambda> at 0x00000281615B0E00>>, 'perms': PermWrapper(<SimpleLazyObject: <function AuthenticationMiddleware.process_request.<locals>.<lambda> at 0x00000281615B0E00>>), 'messages': <FallbackStorage: request=<WSGIRequest: GET '/trading/portafolio/'>>, 'DEFAULT_MESSAGE_LEVELS': {'DEBUG': 10, 'INFO': 20, 'SUCCESS': 25, 'WARNING': 30, 'ERROR': 40}}, {}, {'portafolio': []}]"}
{"asctime": "2025-05-25 14:31:42,247", "levelname": "DEBUG", "name": "django.template", "module": "base", "funcName": "_resolve_lookup", "lineno": 941, "message": "Exception while resolving variable 'saldo' in template 'trading/portafolio.html'.", "exc_info": "Traceback (most recent call last):\n  File \"C:\\Users\\Eliana Galban\\AccionesElBosque\\venv\\Lib\\site-packages\\django\\template\\base.py\", line 891, in _resolve_lookup\n    current = current[bit]\n              ~~~~~~~^^^^^\n  File \"C:\\Users\\Eliana Galban\\AccionesElBosque\\venv\\Lib\\site-packages\\django\\template\\context.py\", line 88, in __getitem__\n    raise KeyError(key)\nKeyError: 'saldo'\n\nDuring handling of the above exception, another exception occurred:\n\nTraceback (most recent call last):\n  File \"C:\\Users\\Eliana Galban\\AccionesElBosque\\venv\\Lib\\site-packages\\django\\template\\base.py\", line 897, in _resolve_lookup\n    if isinstance(current, BaseContext) and getattr(\n                                            ^^^^^^^^\nAttributeError: type object 'RequestContext' has no attribute 'saldo'\n\nDuring handling of the above exception, another exception occurred:\n\nTraceback (most recent call last):\n  File \"C:\\Users\\Eliana Galban\\AccionesElBosque\\venv\\Lib\\site-packages\\django\\template\\base.py\", line 907, in _resolve_lookup\n    current = current[int(bit)]\n                      ^^^^^^^^\nValueError: invalid literal for int() with base 10: 'saldo'\n\nDuring handling of the above exception, another exception occurred:\n\nTraceback (most recent call last):\n  File \"C:\\Users\\Eliana Galban\\AccionesElBosque\\venv\\Lib\\site-packages\\django\\template\\base.py\", line 914, in _resolve_lookup\n    raise VariableDoesNotExist(\ndjango.template.base.VariableDoesNotExist: Failed lookup for key [saldo] in [{'True': True, 'False': False, 'None': None}, {'csrf_token': <SimpleLazyObject: <function csrf.<locals>._get_val at 0x00000281615B09A0>>, 'request': <WSGIRequest: GET '/trading/portafolio/'>, 'user': <SimpleLazyObject: <function AuthenticationMiddleware.process_request.<locals>.<lambda> at 0x00000281615B00E0>>, 'perms': PermWrapper(<SimpleLazyObject: <function AuthenticationMiddleware.process_request.<locals>.<lambda> at 0x00000281615B00E0>>), 'messages': <FallbackStorage: request=<WSGIRequest: GET '/trading/portafolio/'>>, 'DEFAULT_MESSAGE_LEVELS': {'DEBUG': 10, 'INFO': 20, 'SUCCESS': 25, 'WARNING': 30, 'ERROR': 40}}, {}, {'portafolio': []}]"}
{"asctime": "2025-05-25 14:33:48,475", "levelname": "DEBUG", "name": "django.template", "module": "base", "funcName": "_resolve_lookup", "lineno": 941, "message": "Exception while resolving variable 'saldo' in template 'trading/portafolio.html'.", "exc_info": "Traceback (most recent call last):\n  File \"C:\\Users\\Eliana Galban\\AccionesElBosque\\venv\\Lib\\site-packages\\django\\template\\base.py\", line 891, in _resolve_lookup\n    current = current[bit]\n              ~~~~~~~^^^^^\n  File \"C:\\Users\\Eliana Galban\\AccionesElBosque\\venv\\Lib\\site-packages\\django\\template\\context.py\", line 88, in __getitem__\n    raise KeyError(key)\nKeyError: 'saldo'\n\nDuring handling of the above exception, another exception occurred:\n\nTraceback (most recent call last):\n  File \"C:\\Users\\Eliana Galban\\AccionesElBosque\\venv\\Lib\\site-packages\\django\\template\\base.py\", line 897, in _resolve_lookup\n    if isinstance(current, BaseContext) and getattr(\n                                            ^^^^^^^^\nAttributeError: type object 'RequestContext' has no attribute 'saldo'\n\nDuring handling of the above exception, another exception occurred:\n\nTraceback (most recent call last):\n  File \"C:\\Users\\Eliana Galban\\AccionesElBosque\\venv\\Lib\\site-packages\\django\\template\\base.py\", line 907, in _resolve_lookup\n    current = current[int(bit)]\n                      ^^^^^^^^\nValueError: invalid literal for int() with base 10: 'saldo'\n\nDuring handling of the above exception, another exception occurred:\n\nTraceback (most recent call last):\n  File \"C:\\Users\\Eliana Galban\\AccionesElBosque\\venv\\Lib\\site-packages\\django\\template\\base.py\", line 914, in _resolve_lookup\n    raise VariableDoesNotExist(\ndjango.template.base.VariableDoesNotExist: Failed lookup for key [saldo] in [{'True': True, 'False': False, 'None': None}, {'csrf_token': <SimpleLazyObject: <function csrf.<locals>._get_val at 0x000001B6D8CA5A80>>, 'request': <WSGIRequest: GET '/trading/portafolio/'>, 'user': <SimpleLazyObject: <function AuthenticationMiddleware.process_request.<locals>.<lambda> at 0x000001B6D8CF39C0>>, 'perms': PermWrapper(<SimpleLazyObject: <function AuthenticationMiddleware.process_request.<locals>.<lambda> at 0x000001B6D8CF39C0>>), 'messages': <FallbackStorage: request=<WSGIRequest: GET '/trading/portafolio/'>>, 'DEFAULT_MESSAGE_LEVELS': {'DEBUG': 10, 'INFO': 20, 'SUCCESS': 25, 'WARNING': 30, 'ERROR': 40}}, {}, {'portafolio': []}]"}
